Workbook
Name ÇALIŞILAN_FİRMA__SEÇ: 'ANA SAYFA'!$B$1
Name ÇALIŞILAN_FİRMA_SEÇ: 'ANA SAYFA'!$B$1

Sheet ANA SAYFA
A1: S.N | B1: ADI SOYADI | C1: GÖREVİ | D1: T.C. KİMLİK NO | E1: İŞE GİRİŞ TARİHİ | F1: DOĞUM TARİHİ | G1: KALAN (-/+)
A2: 1 | B2: ALİ AYDEMİR | C2: TIR-ÇEKİCİ ŞOFÖRÜ | D2: 41578181364 | E2: 43654 | F2: 25651 | G2: ='1'!I41 -> 24 | I2: YILLIK İZNİN KULLANILMASI 4857 Sayılı İş Yasasının 53’ Üncü maddesine göre işyerinde işe başladığı tarihten itibaren, deneme süreside içinde olmak kaydıyla, en Az 1 yıl çalışmış olan işçilere, yıllık izin verilmesi gerekmektedir. Nitelikleri gereği bir yıldan az süren mevsim veya kampanya işlerinde çalışanlar hakkında yıllık izin hükümleri uygulanmayacaktır. Yıllık izne ait hususların emrediciliği nedeniyle bu haktan vazgeçilmesi mümkün değildir. Dolayısıyla yıllık izin kullanmama taahhüdü yahut zorunluluğu içeren sözleşme hükümlerinin yok sayılması gerekmektedir. Yasanın 53’ Üncü maddesine ve yönetmeliğin 9’uncu maddesi uyarınca işçilere verilmesi gereken yıllık izin sürelerinin, hizmet süresi • 1 yıldan 5 yıla kadar(5 yıl dahil) olanlara 14 günden, • 5 yıldan fazla 15 yıldan az olanlara 20 günden, • 15 yıl (dahil) ve daha fazla olanlara 26 günden az olmaması • 18 ve daha küçük yaşta olan işçilere ve 50 ve daha fazla yaştaki işçilere verilecek izin süresinin de 20 günden az olmaması gerekmektedir.
A3: 2 | B3: AHMET EMİN EFEOĞLU | C3: KAMYON ŞOFÖRÜ | D3: 16702793522 | E3: 43281 | F3: 21886 | G3: ='2'!H40 -> 95.5
A4: 3 | B4: ALİ TASLAK | C4: İNŞAAT USTASI | D4: 67282150540 | E4: 41075 | F4: 24899 | G4: ='3'!H73 -> 77
A5: 4 | B5: BAYRAM CAN YILMAZ | C5: TIR-ÇEKİCİ ŞOFÖRÜ | D5: 31268318552 | E5: 46078 | F5: 36392 | G5: ='4'!H35 -> -1
A6: 5 | B6: AVNİ ÖZGÜR | C6: TIR-ÇEKİCİ ŞOFÖRÜ | D6: 23270269090 | E6: 44355 | F6: 24001 | G6: ='5'!H40 -> 32
A7: 6 | B7: BEKİR BAHAR | C7: MUHASEBE ŞEFİ | D7: 11517017542 | E7: 41288 | F7: 30225 | G7: ='6'!H38 -> 95
A8: 7 | B8: CELAL UNSUR | C8: KAYNAKÇI | D8: 52795285216 | E8: 43745 | F8: 22335 | G8: ='7'!H53 -> -14.5
A9: 8 | B9: DOĞAN NESANIR | C9: EKSKAVATÖR OPERATÖR | D9: 19895542946 | E9: 44372 | F9: 25692 | G9: ='8'!H30 -> 35.5
A10: 9 | B10: EMİN İLHAN | C10: MADEN MÜHENDİSİ | D10: 13235872786 | E10: 42873 | F10: 30453 | G10: ='9'!H32 -> 85
A11: 10 | B11: MUHAMMETCAN GÜNDOĞDU | C11: İŞ MAKİNELERİ YAĞCISI | D11: 39382583696 | E11: 45870 | F11: 39326 | G11: ='10'!H47 -> -1
A12: 11 | B12: EYÜP ÇELENK | C12: DOZER OPERATÖR | D12: 38564093244 | E12: 44196 | F12: 24504 | G12: ='11'!H36 -> 38.5
A13: 12 | B13: ÇETİN ÖZYÜKSEL | C13: KAYNAKCI | D13: 49729730652 | E13: 45170 | F13: 27708 | G13: ='12'!H29 -> -4.5
A14: 13 | B14: SATILMIŞ ÇAKAR | C14: BEKO LODER OPT. | D14: 45814447276 | E14: 45527 | F14: 27507 | G14: ='13'!H36 -> 9
A15: 14 | B15: HİLMİ ÖZDEMİR | C15: OPERATÖR | D15: 50626705742 | E15: 41477 | F15: 26104 | G15: ='14'!H36 -> 19
A16: 15 | B16: HASAN KURT | C16: SATIN ALMA SORUMLUSU | D16: 10017059328 | E16: 45477 | F16: 33492 | G16: ='15'!H33 -> 4
A17: 16 | B17: HÜSAMETTİN GÜLTEKİN | C17: KÜREKÇİ | D17: 40033015848 | E17: 44937 | F17: 30752 | G17: ='16'!H39 -> 29.5
A18: 17 | B18: AHMET SAVAŞ | C18: KAMYON ŞOFÖRÜ | D18: 28546398634 | E18: 44928 | F18: 25461 | G18: ='17'!H37 -> 39
A19: 18 | B19: ALPEREN TORUK | C19: TIR-ÇEKİCİ ŞOFÖRÜ | D19: 29221711892 | E19: 45434 | F19: 36442 | G19: ='18'!H31 -> 17
A20: 19 | B20: İBRAHİM KURT | C20: İŞ MAK. BAKIM VE ONARIM | D20: 69652051396 | E20: 44601 | F20: 27792 | G20: ='19'!H30 -> 0.5
A21: 20 | B21: İBRAHİM SEVEN | C21: TIR ŞOFÖRÜ | D21: 28438730016 | E21: 44946 | F21: 28074 | G21: ='20'!H43 -> 11 | I21: MAZERET DURUMU | P21: 4857 Sayılı İş Kanunu | S21: 657 Sayılı Devlet Memurları Kanunu
A22: 21 | B22: EMİRHAN GÜRBÜZ | C22: İŞ MAKİNELERİ YAĞCISI | D22: 20473884860 | E22: 45568 | F22: 38058 | G22: ='21'!H35 -> -4 | I22: Evlenmesi Halinde | P22: 3 gün | S22: 7 gün
A23: 22 | B23: DOĞAN YAĞMUR | C23: KAMYON ŞOFÖRÜ | D23: 59386205738 | E23: 45418 | F23: 31973 | G23: ='22'!H40 -> 16 | I23: Çoçuğun Evlenmesi Halinde | P23: * | S23: 7 gün
A24: 23 | B24: NEVZAT KAŞIKÇI | C24: BULDOZER OPERATÖRÜ | D24: 39316375052 | E24: 45404 | F24: 22945 | G24: ='23'!H37 -> 4 | I24: Anne, Baba, Eş veya çoçuğun ölmesi halinde | P24: 3 gün | S24: 7 gün
A25: 24 | B25: MUSTAFA ŞENOL SANCAK | C25: ENDÜSTRİYEL İLİŞKİLER VE PERSONEL İLİŞKİLERİ | D25: 19988726864 | E25: 45124 | F25: 24108 | G25: ='24'!H39 -> 2 | I25: Eşinin Anne Babasının veya Kardeşinin Ölmesi Halinde | P25: * | S25: 7 gün
A26: 25 | B26: HASAN AKÇAYOĞLU | C26: KAMYON ŞOFÖRÜ | D26: 47494140430 | E26: 46056 | F26: 27560 | G26: ='25'!H37 -> -1 | I26: Eşin Doğum Yapması Halinde | P26: 10 gün | S26: 10 gün
A27: 26 | B27: MESUT YILMAZ | C27: USTA YARDIMCISI | D27: 39817657916 | E27: 41803 | F27: 31925 | G27: ='26'!H56 -> 3.5 | I27: Engelli Çocuğu Halinde | P27: 10 gün | S27: 10 gün
A28: 27 | B28: MUHAMMET MUSTAFA KOÇYİĞİT | C28: KEPÇE OPERATÖR | D28: 41989739482 | E28: 43948 | F28: 33312 | G28: ='27'!H29 -> 33 | I28: Kardeşinin Ölmesi Halinde | P28: 3 gün | S28: 7 gün
A29: 28 | B29: MUHAMMED AYDIN | C29: EKSKAVATÖR OPERATÖRÜ | D29: 42727968904 | E29: 44356 | F29: 31968 | G29: ='28'!H32 -> 4.5 | I29: Emzirme İzni | P29: 1,5 saat | S29: 6 ay için 3 saat 2.ci 6 ay için 1,5 saat
A30: 29 | B30: MUHİTTİN DEMİR | C30: KAMYON ŞOFÖRÜ | D30: 12361925380 | E30: 45442 | F30: 22324 | G30: ='29'!H37 -> 33
A31: 30 | B31: MUHSİN ZEDEF | C31: BEKÇİ | D31: 10982000370 | E31: 43560 | F31: 21491 | G31: ='30'!H30 -> 106 | I31: İhbar Bildirim (İşçi ve İşveren)
A32: 31 | B32: MURAT ÖZSUBAŞI | C32: EKSKAVATÖR OPERATÖRÜ | D32: 31463194012 | E32: 41505 | F32: 26826 | G32: ='31'!H70 -> 20.5 | I32: 0 - 6 Ay | M32: 2 | N32: Hafta
A33: 32 | B33: MUSTAFA İSPİR | C33: BEKO LODER OPT. | D33: 56986627380 | E33: 45552 | F33: 35818 | G33: ='32'!H34 -> 10.5 | I33: 6 - 1,5 Yıl | M33: 4 | N33: Hafta
A34: 33 | B34: MUSTAFA DEMİRALAY | C34: TIR-ÇEKİCİ ŞOFÖRÜ | D34: 61396483426 | E34: 45362 | F34: 25781 | G34: ='33'!H54 -> 0 | I34: 1,5 - 3 Yıl | M34: 6 | N34: Hafta
A35: 34 | B35: MUSTAFA YALVAÇ | C35: BEDEN İŞCİSİ | D35: 12598524950 | E35: 44567 | F35: 22749 | G35: ='34'!H44 -> 7 | I35: 3 Yıl ve Üstü | M35: 8 | N35: Hafta
A36: 35 | B36: ERHAN AYDEMİR | C36: KANTAR GÖREVLİSİ | D36: 11219671110 | E36: 44211 | F36: 32441 | G36: ='35'!H38 -> 21
A37: 36 | B37: MÜMİN AKÇİN | C37: OPERATÖR | D37: 12254984746 | E37: 44992 | F37: 27211 | G37: ='36'!H54 -> 11.5
A38: 37 | B38: MEHMET CEMİL ÇETİN | C38: TIR-ÇEKİCİ ŞOFÖRÜ | D38: 20401800252 | E38: 44985 | F38: 25821 | G38: ='37'!H36 -> -0.5
A39: 38 | B39: NİHAT ÖZGEL | C39: KAMYON ŞOFÖRÜ | D39: 49831847958 | E39: 43984 | F39: 23377 | G39: ='38'!H45 -> 27
A40: 39 | B40: NURETTİN AYDIN | C40: DOZER OPERATÖR | D40: 25240844054 | E40: 43029 | F40: 22051 | G40: ='39'!H63 -> 58.5
...

Sheet 1
B1: ADI SOYADI | C1: ='ANA SAYFA'!B2 -> ALİ AYDEMİR | D1: PERSONEL İZİN ÇİZELGESİ | K1: Ana Sayfa
B2: T.C.KİMLİK NO | C2: ='ANA SAYFA'!D2 -> 41578181364
B3: GÖREVİ | C3: ='ANA SAYFA'!C2 -> TIR-ÇEKİCİ ŞOFÖRÜ
B4: İŞE GİRİŞ TARİHİ | C4: ='ANA SAYFA'!E2 -> 43654
B5: DOĞUM TARİHİ | C5: ='ANA SAYFA'!F2 -> 25651
A6: PERSONEL İZİN ÇİZELGESİ
B7: İZİN NEDENİ | C7: İZİNE ÇIKIŞ TARİHİ | D7: İZİNDEN DÖNÜŞ TARİHİ | E7: İZİNE ÇIKIŞ SAATİ | F7: İZİNDEN DÖNÜŞ SAATİ | G7: İZNİ KAZANDIĞI TARİH ARALIĞI | H7: SENELİK İZİN HAKKI TUTARI | I7: KULLANILAN İZİN TUTARI
C8: 43846 | D8: 43855 | E8: 0.33333333 | F8: 0.33333333 | G8: 08.07.19-08.07.20 | H8: 14 | I8: 2
C9: 43904 | D9: 43909 | E9: 0.33333333 | F9: 0.33333333 | G9: 08.07.20-08.07.21 | H9: 20 | I9: 3
C10: 43916 | D10: 43923 | E10: 0.33333333 | F10: 0.33333333 | G10: 08.07.21-08.07.22 | H10: 20 | I10: 2
C11: 44179 | D11: 44180 | E11: 0.33333333 | F11: 0.33333333 | G11: 08.07.22-08.07.23 | H11: 20 | I11: 4
C12: 44223 | D12: 44225 | E12: 0.41666667 | F12: 0.33333333 | G12: 08.07.23-08.07.24 | H12: 20 | I12: 1
C13: 44279 | D13: 44284 | E13: 0.33333333 | F13: 0.33333333 | G13: 08.07.24-08.07.25 | H13: 20 | I13: 1
C14: 44349 | D14: 44351 | E14: 0.33333333 | F14: 0.33333333 | I14: 2
C15: 44445 | D15: 44448 | E15: 0.33333333 | F15: 0.33333333 | I15: 3
C16: 44519 | D16: 44520 | E16: 0.33333333 | F16: 0.33333333 | I16: 2
C17: 44746 | D17: 44757 | E17: 0.33333333 | F17: 0.33333333 | I17: 6
C18: 44861 | D18: 44865 | E18: 0.33333333 | F18: 0.33333333 | I18: 3
C19: 44985 | D19: 44988 | E19: 0.33333333 | F19: 0.33333333 | I19: 3
C20: 45101 | D20: 45110 | E20: 0.33333333 | F20: 0.33333333 | I20: 2
C21: 45141 | D21: 45154 | E21: 0.33333333 | F21: 0.33333333 | I21: 11
C22: 45229 | D22: 45236 | E22: 0.33333333 | F22: 0.33333333 | I22: 5
C23: 06.05.2024 PAZARTESİ | D23: 20.05.2024 PAZARTESİ | I23: 12
C24: 45624 | D24: 45628 | I24: 4
C25: 45633 | D25: 45635 | I25: 3
C26: 45667 | D26: 45675 | I26: 8
C27: 45880 | D27: 45894 | E27: 0.33333333 | F27: 0.33333333 | I27: 12
C28: 46199 | D28: 46200 | I28: 1
G39: TOPLAMLAR | H39: =SUM(H8:H38) -> 114 | I39: =SUM(I8:I38) -> 90
G41: KALAN FARK(-/+) | I41: =H39-I39 -> 24

Sheet 2
A1: ADI SOYADI | B1: ='ANA SAYFA'!B3 -> AHMET EMİN EFEOĞLU | C1: PERSONEL İZİN ÇİZELGESİ
A2: T.C.KİMLİK NO | B2: ='ANA SAYFA'!D3 -> 16702793522
A3: GÖREVİ | B3: ='ANA SAYFA'!C3 -> KAMYON ŞOFÖRÜ
A4: İŞE GİRİŞ TARİHİ | B4: ='ANA SAYFA'!E3 -> 43281
A5: DOĞUM TARİHİ | B5: ='ANA SAYFA'!F3 -> 21886
A6: PERSONEL İZİN ÇİZELGESİ | J6: Ana Sayfa
A7: İZİN NEDENİ | B7: İZİNE ÇIKIŞ TARİHİ | C7: İZİNDEN DÖNÜŞ TARİHİ | D7: İZİNE ÇIKIŞ SAATİ | E7: İZİNDEN DÖNÜŞ SAATİ | F7: İZNİ KAZANDIĞI TARİH ARALIĞI | G7: SENELİK İZİN HAKKI TUTARI | H7: KULLANILAN İZİN TUTARI
B8: 43393 | C8: 43394 | D8: 0.33333333 | E8: 0.33333333 | F8: 30.06.18-30.06.19 | G8: 20 | H8: 1
B9: 43414 | C9: 43415 | D9: 0.5 | E9: 0.33333333 | F9: 30.06.19-30.06.20 | G9: 20 | H9: 0.5
B10: 43419 | C10: 43421 | D10: 0.33333333 | E10: 0.33333333 | F10: 30.06.21-30.06.22 | G10: 20 | H10: 2
B11: 20 Kasım 2018 Cumartesi | C11: 21 Kasım 2018 Pazar | D11: 0.33333333 | E11: 0.33333333 | F11: 30.06.22-30.06.23 | G11: 20 | H11: 1
F12: 30.06.23-30.06.24 | G12: 20
F38: TOPLAMLAR | G38: =SUM(G8:G37) -> 100 | H38: =SUM(H8:H37) -> 4.5
F40: KALAN FARK(-/+) | H40: =G38-H38 -> 95.5

Sheet 3
A1: ADI SOYADI | B1: ALİ TASLAK | C1: PERSONEL İZİN ÇİZELGESİ
A2: T.C.KİMLİK NO | B2: 67282150540
A3: GÖREVİ | B3: İNŞAAT USTASI
A4: İŞE GİRİŞ TARİHİ | B4: 41075
A5: DOĞUM TARİHİ | B5: 24899
A6: PERSONEL İZİN ÇİZELGESİ | J6: Ana Sayfa | L6: 45898 | M6: e kadar tazminatını aldı
A7: İZİN NEDENİ | B7: İZİNE ÇIKIŞ TARİHİ | C7: İZİNDEN DÖNÜŞ TARİHİ | D7: İZİNE ÇIKIŞ SAATİ | E7: İZİNDEN DÖNÜŞ SAATİ | F7: İZNİ KAZANDIĞI TARİH ARALIĞI | G7: SENELİK İZİN HAKKI TUTARI | H7: KULLANILAN İZİN TUTARI | L7: 45899 | M7: YENİ KIDEMİ BAŞLADI
B8: 41263 | C8: 41267 | D8: 0.54166667 | E8: 0.33333333 | F8: 15.06.12-15.06.13 | G8: 14 | H8: 3 | L8: 45898 | M8: emekli oldu kıdemi hesaplandı henüz verilmedi
B9: 41282 | C9: 41283 | D9: 0.33333333 | E9: 0.33333333 | F9: 15.06.13-15.06.14 | G9: 14 | H9: 1
B10: 41313 | C10: 41314 | D10: 0.54166667 | E10: 0.33333333 | F10: 15.06.14-15.06.15 | G10: 14 | H10: 0.5
B11: 41341 | C11: 41342 | D11: 0.54166667 | E11: 0.33333333 | F11: 15.06.15-15.06.16 | G11: 14 | H11: 0.5
B12: 41372 | C12: 41342 | D12: 0.58333333 | E12: 0.3125 | F12: 15.06.16-15.06.17 | G12: 14 | H12: 0.5
B13: 41401 | C13: 41402 | D13: 0.5 | E13: 0.3125 | F13: 15.06.17-15.06.18 | G13: 20 | H13: 0.5
B14: 41409 | C14: 41410 | D14: 0.54166667 | E14: 0.3125 | F14: 15.06.18-15.06.19 | G14: 20 | H14: 0.5
B15: 41435 | C15: 41436 | D15: 0.45833333 | E15: 0.3125 | F15: 15.06.19-15.06.20 | G15: 20 | H15: 0.5
B16: 41453 | C16: 41454 | D16: 0.5625 | E16: 0.3125 | F16: 15.06.20-15.06.21 | G16: 20 | H16: 0.5
B17: 41549 | C17: 41550 | D17: 0.60416667 | E17: 0.33333333 | F17: 15.06.21-15.06.22 | G17: 20 | H17: 0.5
B18: 41691 | C18: 41327 | D18: 0.5625 | E18: 0.33333333 | F18: 15.06.22-15.06.23 | G18: 20 | H18: 0.5
B19: 41768 | C19: 41770 | D19: 0.58333333 | E19: 0.33333333 | F19: 15.06.23-15.06.24 | G19: 20 | H19: 1.5
B20: 42116 | C20: 42117 | D20: 0.6125 | E20: 0.33333333 | F20: 15.06.24-15.06.25 | G20: 20 | H20: 0.5
B21: 43225 | C21: 43226 | D21: 0.33333333 | E21: 0.33333333 | H21: 1
B22: 43357 | C22: 43358 | D22: 0.33333333 | E22: 0.33333333 | H22: 1
B23: 43297 | C23: 43298 | D23: 0.58333333 | E23: 0.33333333 | H23: 0.5
B24: 43368 | C24: 43372 | D24: 0.33333333 | E24: 0.33333333 | H24: 5
B25: 43424 | C25: 43425 | D25: 0.33333333 | E25: 0.33333333 | H25: 1
B26: 43431 | C26: 43433 | D26: 0.33333333 | E26: 0.33333333 | H26: 2
B27: 43501 | C27: 43507 | D27: 0.33333333 | E27: 0.33333333 | H27: 6
B28: 43535 | C28: 43539 | D28: 0.33333333 | E28: 0.33333333 | H28: 4
B29: 43571 | C29: 43572 | D29: 0.33333333 | E29: 0.33333333 | H29: 1
B30: 43603 | C30: 43604 | D30: 0.33333333 | E30: 0.33333333 | H30: 1
B31: 43721 | C31: 43722 | D31: 0.33333333 | E31: 0.33333333 | H31: 1
B32: 43754 | C32: 43756 | D32: 0.33333333 | E32: 0.33333333 | H32: 2
... B39: 44210 | C39: 44212 | D39: 0.5 | E39: 0.33333333 | H39: 2.5
B40: 44242 | C40: 44249 | D40: 08.00 | E40: 0.33333333 | H40: 6
B41: 44278 | C41: 44279 | D41: 0.33333333 | E41: 0.33333333 | H41: 1
B42: 44279 | C42: 44281 | D42: 0.33333333 | E42: 0.33333333 | H42: 2
B43: 44225 | C43: 44287 | D43: 0.33333333 | E43: 0.33333333 | H43: 3
B44: 44389 | C44: 44394 | D44: 0.33333333 | E44: 0.33333333 | H44: 5
B45: 44544 | C45: 44548 | D45: 0.33333333 | E45: 0.75 | H45: 5
B46: 44587 | C46: 44590 | D46: 0.33333333 | E46: 0.33333333 | H46: 3
...

Sheet 4
A1: ADI SOYADI | B1: ='ANA SAYFA'!B5 -> BAYRAM CAN YILMAZ | C1: PERSONEL İZİN ÇİZELGESİ | J1: ANA SAYFA
A2: T.C.KİMLİK NO | B2: ='ANA SAYFA'!D5 -> 31268318552
A3: GÖREVİ | B3: ='ANA SAYFA'!C5 -> TIR-ÇEKİCİ ŞOFÖRÜ
A4: İŞE GİRİŞ TARİHİ | B4: ='ANA SAYFA'!E5 -> 46078
A5: DOĞUM TARİHİ | B5: ='ANA SAYFA'!F5 -> 36392
A6: İZİN NEDENİ | B6: İZİNE ÇIKIŞ TARİHİ | C6: İZİNDEN DÖNÜŞ TARİHİ | D6: İZİNE ÇIKIŞ SAATİ | E6: İZİNDEN DÖNÜŞ SAATİ | F6: İZNİ KAZANDIĞI TARİH ARALIĞI | G6: SENELİK İZİN HAKKI TUTARI | H6: KULLANILAN İZİN TUTARI
B7: 46099 | C7: 46100 | H7: 1
F33: TOPLAMLAR | G33: =SUM(G7:G32) -> 0 | H33: =SUM(H7:H32) -> 1
F35: KALAN FARK(-/+) | H35: =G33-H33 -> -1

Sheet 5
A1: ADI SOYADI | B1: ='ANA SAYFA'!B6 -> AVNİ ÖZGÜR | C1: PERSONEL İZİN ÇİZELGESİ
A2: T.C.KİMLİK NO | B2: ='ANA SAYFA'!D6 -> 23270269090
A3: GÖREVİ | B3: ='ANA SAYFA'!C6 -> TIR-ÇEKİCİ ŞOFÖRÜ
A4: İŞE GİRİŞ TARİHİ | B4: ='ANA SAYFA'!E6 -> 44355
A5: DOĞUM TARİHİ | B5: ='ANA SAYFA'!F6 -> 24001
A6: PERSONEL İZİN ÇİZELGESİ | J6: Ana Sayfa
A7: İZİN NEDENİ | B7: İZİNE ÇIKIŞ TARİHİ | C7: İZİNDEN DÖNÜŞ TARİHİ | D7: İZİNE ÇIKIŞ SAATİ | E7: İZİNDEN DÖNÜŞ SAATİ | F7: İZNİ KAZANDIĞI TARİH ARALIĞI | G7: SENELİK İZİN HAKKI TUTARI | H7: KULLANILAN İZİN TUTARI
B8: 44526 | C8: 44527 | D8: 0.33333333 | E8: 0.33333333 | F8: 08.06.21-08.06.22 | G8: 20 | H8: 1
B9: 45052 | C9: 45054 | D9: 0.33333333 | E9: 0.33333333 | F9: 08.06.22-08.06.23 | G9: 20 | H9: 1
B10: 45157 | C10: 45159 | D10: 0.33333333 | E10: 0.33333333 | F10: 08.06.23-08.06.24 | G10: 20 | H10: 1
B11: 45248 | C11: 45250 | D11: 0.33333333 | E11: 0.33333333 | F11: 08.06.24-08.06.25 | G11: 20 | H11: 1
B12: 45356 | C12: 45369 | D12: 0.33333333 | E12: 0.33333333 | F12: 08. 06.25-08.06.26 | G12: 20 | H12: 11
B13: 27.05.2024 Pazartesi | C13: 45456 | D13: 0.33333333 | E13: 0.33333333 | H13: 15
B14: 45535 | C14: 45535 | D14: 0.33333333 | E14: 0.33333333 | H14: 1
B15: 45677 | C15: 45677 | D15: 0.33333333 | E15: 0.33333333 | H15: 1
B16: 45790 | C16: 45791 | D16: 0.33333333 | E16: 0.33333333 | H16: 2
B17: 45878 | C17: 45880 | D17: 0.33333333 | E17: 0.33333333 | H17: 0.5
B18: 45887 | C18: 45894 | D18: 0.33333333 | E18: 0.33333333 | H18: 6
B19: 45908 | C19: 45922 | D19: 0.33333333 | E19: 0.33333333 | H19: 12
B20: 45964 | C20: 45976 | D20: 0.54166667 | E20: 0.33333333 | H20: 11.5
B21: 46191 | C21: 46192 | H21: 1
B22: 46195 | C22: 46197 | H22: 2
B23: 46202 | C23: 46203 | H23: 1
F38: TOPLAMLAR | G38: =SUM(G8:G37) -> 100 | H38: =SUM(H8:H37) -> 68
F40: KALAN FARK(-/+) | H40: =G38-H38 -> 32

Sheet 6
A1: ADI SOYADI | B1: ='ANA SAYFA'!B7 -> BEKİR BAHAR | C1: PERSONEL İZİN ÇİZELGESİ
A2: T.C.KİMLİK NO | B2: ='ANA SAYFA'!D7 -> 11517017542
A3: GÖREVİ | B3: ='ANA SAYFA'!C7 -> MUHASEBE ŞEFİ
A4: İŞE GİRİŞ TARİHİ | B4: ='ANA SAYFA'!E7 -> 41288
A5: DOĞUM TARİHİ | B5: ='ANA SAYFA'!F7 -> 30225
A6: PERSONEL İZİN ÇİZELGESİ | J6: Ana Sayfa
A7: İZİN NEDENİ | B7: İZİNE ÇIKIŞ TARİHİ | C7: İZİNDEN DÖNÜŞ TARİHİ | D7: İZİNE ÇIKIŞ SAATİ | E7: İZİNDEN DÖNÜŞ SAATİ | F7: İZNİ KAZANDIĞI TARİH ARALIĞI | G7: SENELİK İZİN HAKKI TUTARI | H7: KULLANILAN İZİN TUTARI
B8: 42296 | C8: 42310 | D8: 0.33333333 | E8: 0.33333333 | F8: 14.01.2013-14.01.2014 | G8: 14 | H8: 11
B9: 42559 | C9: 42562 | D9: 0.33333333 | E9: 0.33333333 | F9: 14.01.2014-14.01.2015 | G9: 14 | H9: 2
B10: 8 Eylül 2016 Perşembe | C10: 16 Eylül 2016 Cuma | D10: 0.33333333 | E10: 0.33333333 | F10: 14.01.2015-14.01.2016 | G10: 14 | H10: 3
B11: 42662 | C11: 42676 | D11: 0.33333333 | E11: 0.33333333 | F11: 14.01.2016-14.01.2017 | G11: 14 | H11: 11
B12: 42700 | C12: 42702 | D12: 0.33333333 | E12: 0.33333333 | F12: 14.01.2017-14.01.2018 | G12: 14 | H12: 1
B13: 42909 | C13: 42919 | D13: 0.33333333 | E13: 0.33333333 | F13: 14.01.2018-14.01.2019 | G13: 20 | H13: 5
B14: 9 Ağustos 2017 Çarşamba | C14: 25 Ağustos 2017 Cuma | D14: 0.33333333 | E14: 0.33333333 | F14: 14.01.2019-14.01.2020 | G14: 20 | H14: 10
B15: 43325 | C15: 43339 | D15: 0.33333333 | E15: 0.33333333 | F15: 14.01.2020-14.01.2021 | G15: 20 | H15: 6
B16: 43431 | C16: 43432 | D16: 0.33333333 | E16: 0.33333333 | F16: 14.01.2021-14.01.2022 | G16: 20 | H16: 1
B17: 43465 | C17: 43472 | D17: 0.33333333 | E17: 0.33333333 | F17: 14.01.2022-14.01.2023 | G17: 20 | H17: 6
B18: 43582 | C18: 43584 | D18: 0.33333333 | E18: 0.33333333 | F18: 14.01.2023-14.01.2024 | G18: 20 | H18: 1
B19: 43623 | C19: 43626 | D19: 0.33333333 | E19: 0.33333333 | F19: 14.01.2024-14.01.2025 | G19: 20 | H19: 2
B20: 16 Temmuz 2021 Cuma | C20: 19 Temmuz 2021 Pazartesi | D20: 0.33333333 | E20: 0.33333333 | F20: 14.01.2025-14.01.2026 | G20: 20 | H20: 2
B21: 44613 | C21: 25 Şubat 2022 Cuma | D21: 0.33333333 | E21: 0.33333333 | H21: 4
B22: 23 ağustos 2022 Salı | C22: 29 Ağustos 2022 Pazartesi | D22: 0.33333333 | E22: 0.33333333 | H22: 5
B23: 20 Ekim 2022 Perşembe | C23: 7 kasım 2022 Pazartesi | D23: 0.33333333 | E23: 0.33333333 | H23: 14
B24: 45047 | C24: 45048 | D24: 0.33333333 | E24: 0.33333333 | H24: 1
B25: 45098 | C25: 45117 | D25: 0.33333333 | E25: 0.33333333 | H25: 10
B26: 45257 | C26: 45264 | D26: 0.33333333 | E26: 0.33333333 | H26: 5
B27: 45274 | C27: 45275 | D27: 0.33333333 | E27: 0.33333333 | H27: 1
B28: 45302 | C28: 45306 | D28: 0.33333333 | E28: 0.33333333 | H28: 2
B29: 45467 | C29: 45471 | D29: 0.33333333 | E29: 0.33333333 | H29: 5
B30: 45516 | C30: 45535 | D30: 0.33333333 | E30: 0.33333333 | H30: 17
B31: 45617 | C31: 45619 | D31: 0.33333333 | E31: 0.33333333 | H31: 3
B32: 45834 | C32: 45834 | D32: 0.33333333 | E32: 0.33333333 | H32: 1
B33: 45909 | C33: 45922 | D33: 0.33333333 | E33: 0.33333333 | H33: 4
B34: 46098 | C34: 46104 | D34: 0.33333333 | E34: 0.33333333 | H34: 2
F36: TOPLAMLAR | G36: =SUM(G8:G35) -> 230 | H36: =SUM(H8:H35) -> 135
F38: KALAN FARK(-/+) | H38: =G36-H36 -> 95

Sheet 7
A1: ADI SOYADI | B1: ='ANA SAYFA'!B8 -> CELAL UNSUR | C1: PERSONEL İZİN ÇİZELGESİ
A2: T.C.KİMLİK NO | B2: ='ANA SAYFA'!D8 -> 52795285216
A3: GÖREVİ | B3: ='ANA SAYFA'!C8 -> KAYNAKÇI
A4: İŞE GİRİŞ TARİHİ | B4: ='ANA SAYFA'!E8 -> 43745
A5: DOĞUM TARİHİ | B5: ='ANA SAYFA'!F8 -> 22335
A6: İZİN NEDENİ | B6: İZİNE ÇIKIŞ TARİHİ | C6: İZİNDEN DÖNÜŞ TARİHİ | D6: İZİNE ÇIKIŞ SAATİ | E6: İZİNDEN DÖNÜŞ SAATİ | F6: İZNİ KAZANDIĞI TARİH ARALIĞI | G6: SENELİK İZİN HAKKI TUTARI | H6: KULLANILAN İZİN TUTARI | J6: ANA SAYFA
B7: 44106 | C7: 44116 | D7: 0.33333333 | E7: 0.33333333 | F7: 07.10.19-07.10.20 | G7: 20 | H7: 8
B8: 44455 | C8: 44466 | D8: 0.33333333 | E8: 0.33333333 | F8: 07.10.20-07.10.21 | G8: 20 | H8: 9
B9: 44723 | C9: 44724 | D9: 0.33333333 | E9: 0.33333333 | F9: 07.10.21-07.10.22 | G9: 20 | H9: 1
B10: 44725 | C10: 44726 | D10: 0.33333333 | E10: 0.33333333 | F10: 07.10.22-07.10.23 | G10: 20 | H10: 1
B11: 44735 | C11: 44736 | D11: 0.33333333 | E11: 0.33333333 | F11: 07.10.23-07.10.24 | G11: 20 | H11: 1
B12: 44778 | C12: 44778 | D12: 0.33333333 | E12: 0.75 | F12: 07.10.24-07.10.25 | G12: 20 | H12: 1
B13: 44790 | C13: 44790 | D13: 0.33333333 | E13: 0.75 | H13: 1
B14: 26 Ağustos 2022 Cuma | C14: 12 Eylül 2022 Pazartesi | D14: 0.33333333 | E14: 0.33333333 | H14: 13
B15: 44833 | C15: 44833 | D15: 0.33333333 | E15: 0.75 | H15: 1
B16: 44861 | C16: 44862 | D16: 0.33333333 | E16: 0.33333333 | H16: 1
B17: 45157 | C17: 45176 | D17: 0.33333333 | E17: 0.33333333 | H17: 15
B18: 45208 | C18: 45209 | D18: 0.33333333 | E18: 0.33333333 | H18: 1
B19: 45212 | C19: 45215 | D19: 0.33333333 | E19: 0.33333333 | H19: 2
B20: 45218 | C20: 45219 | D20: 0.33333333 | E20: 0.33333333 | H20: 1
B21: 45238 | C21: 45239 | D21: 0.33333333 | E21: 0.33333333 | H21: 1
B22: 45265 | C22: 45271 | D22: 0.33333333 | E22: 0.33333333 | H22: 5
B23: 01.04.2024 PAZARTESİ | C23: 01.04.2024 PAZARTESİ | D23: 0.33333333 | E23: 0.33333333 | H23: 1
B24: 45409 | C24: 45411 | D24: 0.33333333 | E24: 08.00 | H24: 1
B25: 20.05.2024 Pazartesi | C25: 20.05.2024 Pazartesi | D25: 0.33333333 | E25: 08.00 | H25: 1
B26: 45518 | C26: 45524 | D26: 0.33333333 | E26: 08.00 | H26: 6
B27: 45538 | C27: 45549 | D27: 0.33333333 | E27: 08.00 | H27: 11
B28: 111299 | C28: 45556 | D28: 0.33333333 | E28: 08.00 | H28: 1
B29: 45581 | C29: 45581 | D29: 0.33333333 | E29: 08.00 | H29: 1
B30: 45649 | C30: 45649 | D30: 0.33333333 | E30: 08.00 | H30: 1
B31: 45667 | C31: 45668 | D31: 0.33333333 | E31: 08.00 | H31: 2
B32: 45800 | C32: 45801 | D32: 0.33333333 | E32: 08.00 | H32: 2
B33: 45803 | C33: 45803 | D33: 0.33333333 | E33: 08.00 | H33: 1
B34: 45794 | C34: 45794 | D34: 0.54166667 | E34: 0.33333333 | H34: 0.5
B35: 45835 | C35: 45835 | D35: 0.33333333 | E35: 0.33333333 | H35: 1
B36: 45859 | C36: 45859 | D36: 0.33333333 | E36: 0.33333333 | H36: 1
B37: 45882 | C37: 45883 | D37: 0.33333333 | E37: 0.33333333 | H37: 1
B38: 45883 | C38: 45887 | D38: 0.33333333 | E38: 0.33333333 | H38: 3
B39: 45951 | C39: 45952 | H39: 1
B40: 45965 | C40: 45966 | H40: 1
...

Sheet 8
A1: ADI SOYADI | B1: ='ANA SAYFA'!B9 -> DOĞAN NESANIR | C1: PERSONEL İZİN ÇİZELGESİ | J1: Ana Sayfa
A2: T.C.KİMLİK NO | B2: ='ANA SAYFA'!D9 -> 19895542946
A3: GÖREVİ | B3: ='ANA SAYFA'!C9 -> EKSKAVATÖR OPERATÖR
A4: İŞE GİRİŞ TARİHİ | B4: ='ANA SAYFA'!E9 -> 44372
A5: DOĞUM TARİHİ | B5: ='ANA SAYFA'!F9 -> 25692
A6: İZİN NEDENİ | B6: İZİNE ÇIKIŞ TARİHİ | C6: İZİNDEN DÖNÜŞ TARİHİ | D6: İZİNE ÇIKIŞ SAATİ | E6: İZİNDEN DÖNÜŞ SAATİ | F6: İZNİ KAZANDIĞI TARİH ARALIĞI | G6: SENELİK İZİN HAKKI TUTARI | H6: KULLANILAN İZİN TUTARI
B7: 26 Ocak 2022 Çarşamba | C7: 28 Ocak 2022 Cuma | D7: 0.33333333 | E7: 0.33333333 | F7: 25.06.21-25.06.22 | G7: 20 | H7: 2
B8: 9 Eylül 2022 Cuma | C8: 44816 | D8: 0.33333333 | E8: 0.33333333 | F8: 25.06.22-25.06.23 | G8: 20 | H8: 2
B9: 45051 | C9: 45052 | D9: 0.33333333 | E9: 0.33333333 | F9: 25.06.23-25.06.24 | G9: 20 | H9: 1
B10: 45209 | C10: 45213 | D10: 0.33333333 | E10: 0.33333333 | F10: 25.06.24-25.06.25 | G10: 20 | H10: 4
B11: 45254 | C11: 45257 | D11: 0.33333333 | E11: 0.33333333 | H11: 2
B12: 45453 | C12: 45462 | D12: 0.33333333 | E12: 0.33333333 | H12: 5
B13: 3 | C13: 45554 | D13: 0.33333333 | E13: 0.33333333 | H13: 15
B14: 45593 | C14: 45593 | D14: 0.33333333 | E14: 0.33333333 | H14: 1
B15: 45744 | C15: 45744 | D15: 0.5 | E15: 0.33333333 | H15: 0.5
B16: 45792 | C16: 45792 | D16: 0.33333333 | E16: 0.33333333 | H16: 1
B17: 45936 | C17: 45943 | D17: 0.33333333 | E17: 0.33333333 | H17: 6
B18: 46051 | C18: 46052 | H18: 1
B19: 46107 | C19: 46108 | H19: 1
B20: 46165 | C20: 46175 | H20: 3
F28: TOPLAMLAR | G28: =SUM(G7:G27) -> 80 | H28: =SUM(H7:H27) -> 44.5
F30: KALAN FARK(-/+) | H30: =G28-H28 -> 35.5

Sheet 9
A1: ADI SOYADI | B1: ='ANA SAYFA'!B10 -> EMİN İLHAN | C1: PERSONEL İZİN ÇİZELGESİ | J1: ANA SAYFA
A2: T.C.KİMLİK NO | B2: ='ANA SAYFA'!D10 -> 13235872786
A3: GÖREVİ | B3: ='ANA SAYFA'!C10 -> MADEN MÜHENDİSİ
A4: İŞE GİRİŞ TARİHİ | B4: ='ANA SAYFA'!E10 -> 42873
A5: DOĞUM TARİHİ | B5: ='ANA SAYFA'!F10 -> 30453
A6: İZİN NEDENİ | B6: İZİNE ÇIKIŞ TARİHİ | C6: İZİNDEN DÖNÜŞ TARİHİ | D6: İZİNE ÇIKIŞ SAATİ | E6: İZİNDEN DÖNÜŞ SAATİ | F6: İZNİ KAZANDIĞI TARİH ARALIĞI | G6: SENELİK İZİN HAKKI TUTARI | H6: KULLANILAN İZİN TUTARI
B7: 4 Temmuz 2022 Pazartesi | C7: 19 Temmuz 2022 Salı | D7: 0.33333333 | E7: 0.33333333 | F7: 18.05.17-18.05.18 | G7: 14 | H7: 8
B8: 45306 | C8: 45316 | D8: 0.33333333 | E8: 0.33333333 | F8: 18.05.18-18.05.19 | G8: 14 | H8: 9
B9: 45467 | C9: 45472 | D9: 0.33333333 | E9: 0.33333333 | F9: 18.05.19-18.05.20 | G9: 14 | H9: 6
B10: 45506 | C10: 45507 | D10: 0.33333333 | E10: 0.33333333 | F10: 18.05.20-18.05.21 | G10: 14 | H10: 2
F11: 18.05.21-18.05.22 | G11: 14
F12: 18.05.22-18.05.23 | G12: 20
F13: 18.05.23-18.05.24 | G13: 20
F30: TOPLAMLAR | G30: =SUM(G5:G29) -> 110 | H30: =SUM(H7:H29) -> 25
F32: KALAN FARK(-/+) | H32: =G30-H30 -> 85

Sheet 10
A1: ADI SOYADI | B1: ='ANA SAYFA'!B11 -> MUHAMMETCAN GÜNDOĞDU | C1: PERSONEL İZİN ÇİZELGESİ | J1: ANA SAYFA
A2: T.C.KİMLİK NO | B2: ='ANA SAYFA'!D11 -> 39382583696
A3: GÖREVİ | B3: ='ANA SAYFA'!C11 -> İŞ MAKİNELERİ YAĞCISI
A4: İŞE GİRİŞ TARİHİ | B4: ='ANA SAYFA'!E11 -> 45870
A5: DOĞUM TARİHİ | B5: ='ANA SAYFA'!F11 -> 39326
A6: İZİN NEDENİ | B6: İZİNE ÇIKIŞ TARİHİ | C6: İZİNDEN DÖNÜŞ TARİHİ | D6: İZİNE ÇIKIŞ SAATİ | E6: İZİNDEN DÖNÜŞ SAATİ | F6: İZNİ KAZANDIĞI TARİH ARALIĞI | G6: SENELİK İZİN HAKKI TUTARI | H6: KULLANILAN İZİN TUTARI
B7: 46051 | C7: 46052 | H7: 1 | J7: İMZASIZ
F45: TOPLAMLAR | G45: =SUM(G5:G44) -> 0 | H45: =SUM(H7:H44) -> 1
F47: KALAN FARK(-/+) | H47: =G45-H45 -> -1

Sheet 11
A1: ADI SOYADI | B1: ='ANA SAYFA'!B12 -> EYÜP ÇELENK | C1: PERSONEL İZİN ÇİZELGESİ | J1: ANA SAYFA
A2: T.C.KİMLİK NO | B2: ='ANA SAYFA'!D12 -> 38564093244
A3: GÖREVİ | B3: ='ANA SAYFA'!C12 -> DOZER OPERATÖR
A4: İŞE GİRİŞ TARİHİ | B4: ='ANA SAYFA'!E12 -> 44196
A5: DOĞUM TARİHİ | B5: ='ANA SAYFA'!F12 -> 24504
A6: İZİN NEDENİ | B6: İZİNE ÇIKIŞ TARİHİ | C6: İZİNDEN DÖNÜŞ TARİHİ | D6: İZİNE ÇIKIŞ SAATİ | E6: İZİNDEN DÖNÜŞ SAATİ | F6: İZNİ KAZANDIĞI TARİH ARALIĞI | G6: SENELİK İZİN HAKKI TUTARI | H6: KULLANILAN İZİN TUTARI
B7: 3 Mart 2021 Çarşamba | C7: 4 Mart 2021 Çarşamba | D7: 0.60416667 | E7: 0.33333333 | F7: 31.12.20-31.12.21 | G7: 20 | H7: 0.5
B8: 16 Eylül 2021 Perşembe | C8: 27 Eylül 2021 Pazartesi | D8: 0.33333333 | E8: 0.33333333 | F8: 31.12.21-31.12.22 | G8: 20 | H8: 9
B9: 6 Haziran 2022 Pazartesi | C9: 7 Haziran 2022 Salı | D9: 0.33333333 | E9: 0.33333333 | F9: 31.12.22-31.12.23 | G9: 20 | H9: 1
B10: 12 Eylül 20222 Pazartesi | C10: 23 Eylül 2022 Pazartesi | D10: 0.33333333 | E10: 0.33333333 | F10: 31.12.23-31.12.24 | G10: 20 | H10: 10
B11: 45194 | C11: 45208 | D11: 0.33333333 | E11: 0.33333333 | F11: 31.12.24-31.12.25 | G11: 20 | H11: 12
B12: 45495 | C12: 45511 | D12: 0.33333333 | E12: 0.33333333 | H12: 15
B13: 45518 | C13: 45519 | D13: 0.33333333 | E13: 0.33333333 | H13: 2
A14: 1. YAKIN VEFAT | B14: 45696 | C14: 45699 | D14: 0.33333333 | E14: 0.33333333
B15: 45700 | C15: 45703 | D15: 0.33333333 | E15: 0.33333333 | H15: 4
B16: 45806 | C16: 45806 | D16: 0.33333333 | E16: 0.33333333 | H16: 1
B17: 45859 | C17: 45861 | D17: 0.33333333 | E17: 0.33333333 | H17: 3
B18: 45887 | C18: 45888 | D18: 0.33333333 | E18: 0.33333333 | H18: 1
B19: 46099 | C19: 46100 | H19: 1
B20: 46165 | C20: 46174 | H20: 2
F34: TOPLAMLAR | G34: =SUM(G7:G33) -> 100 | H34: =SUM(H7:H33) -> 61.5
F36: KALAN FARK(-/+) | H36: =G34-H34 -> 38.5

Sheet 12
A1: ADI SOYADI | B1: ='ANA SAYFA'!B13 -> ÇETİN ÖZYÜKSEL | C1: PERSONEL İZİN ÇİZELGESİ | J1: Ana Sayfa
A2: T.C.KİMLİK NO | B2: ='ANA SAYFA'!D13 -> 49729730652
A3: GÖREVİ | B3: ='ANA SAYFA'!C13 -> KAYNAKCI
A4: İŞE GİRİŞ TARİHİ | B4: ='ANA SAYFA'!E13 -> 45170
A5: DOĞUM TARİHİ | B5: ='ANA SAYFA'!F13 -> 27708
A6: İZİN NEDENİ | B6: İZİNE ÇIKIŞ TARİHİ | C6: İZİNDEN DÖNÜŞ TARİHİ | D6: İZİNE ÇIKIŞ SAATİ | E6: İZİNDEN DÖNÜŞ SAATİ | F6: İZNİ KAZANDIĞI TARİH ARALIĞI | G6: SENELİK İZİN HAKKI TUTARI | H6: KULLANILAN İZİN TUTARI
B7: 45451 | C7: 45454 | D7: 0.33333333 | E7: 0.33333333 | F7: 1.09.2023-1.09.2024 | G7: 14 | H7: 3
F8: 1.09.2024-1.09.2025 | G8: 14
B9: 45558 | C9: 45558 | D9: 0.5 | E9: 0.33333333 | H9: 0.5
B10: 45563 | C10: 45563 | D10: 0.33333333 | E10: 0.33333333 | H10: 1
B11: 45577 | C11: 45577 | D11: 0.33333333 | E11: 0.33333333 | H11: 1
B12: 45607 | C12: 45607 | D12: 0.33333333 | E12: 0.33333333 | H12: 1
B13: 45654 | C13: 45654 | D13: 0.33333333 | E13: 0.33333333 | H13: 1
B14: 45679 | C14: 45680 | D14: 0.33333333 | E14: 0.33333333 | H14: 2
B15: 45717 | C15: 45717 | D15: 0.33333333 | E15: 0.33333333 | H15: 1
B16: 45829 | C16: 45829 | D16: 0.33333333 | E16: 0.33333333 | H16: 1
B17: 45863 | C17: 45863 | D17: 0.33333333 | E17: 0.33333333 | H17: 1
B18: 45878 | C18: 45880 | D18: 0.33333333 | E18: 0.33333333 | H18: 1
B19: 45894 | C19: 45899 | D19: 0.33333333 | E19: 0.33333333 | H19: 5
B20: 45945 | C20: 45946 | D20: 0.33333333 | E20: 0.33333333 | H20: 1
B21: 45979 | C21: 45980 | D21: 0.33333333 | E21: 0.33333333 | H21: 1
B22: 46024 | C22: 46041 | H22: 14
B23: 46111 | C23: 46112 | H23: 1
B24: MART2026 MAAŞINDAN KESİLDİ | H24: -3
F27: TOPLAMLAR | G27: =SUM(G5:G26) -> 28 | H27: =SUM(H7:H26) -> 32.5
F29: KALAN FARK(-/+) | H29: =G27-H27 -> -4.5

Sheet 13
A1: ADI SOYADI | B1: ='ANA SAYFA'!B14 -> SATILMIŞ ÇAKAR | C1: PERSONEL İZİN ÇİZELGESİ | J1: ANA SAYFA
A2: T.C.KİMLİK NO | B2: ='ANA SAYFA'!D14 -> 45814447276
A3: GÖREVİ | B3: ='ANA SAYFA'!C14 -> BEKO LODER OPT.
A4: İŞE GİRİŞ TARİHİ | B4: ='ANA SAYFA'!E14 -> 45527
A5: DOĞUM TARİHİ | B5: ='ANA SAYFA'!F14 -> 27507
A6: İZİN NEDENİ | B6: İZİNE ÇIKIŞ TARİHİ | C6: İZİNDEN DÖNÜŞ TARİHİ | D6: İZİNE ÇIKIŞ SAATİ | E6: İZİNDEN DÖNÜŞ SAATİ | F6: İZNİ KAZANDIĞI TARİH ARALIĞI | G6: SENELİK İZİN HAKKI TUTARI | H6: KULLANILAN İZİN TUTARI | J6: 45930 | K6: kıdem tazminatını aldı | L6: 45931 | M6: yeni işe girişi
B7: 45570 | C7: 45570 | D7: 0.33333333 | E7: 0.33333333 | F7: 22.08.2024-22.08.2025 | G7: 20 | H7: 1
B8: 45698 | C8: 45699 | D8: 0.33333333 | E8: 0.33333333 | H8: 2
B9: MART 2025 MAAŞINDAN YAPILAN KESİNTİ | H9: -2
B10: NİSAN 2025 MAAŞINDAN YAPILAN KESİNTİ | H10: -1
B11: 45818 | C11: 45819 | H11: 1
B12: 45873 | C12: 45876 | D12: 0.33333333 | E12: 0.33333333 | H12: 3
B13: 45976 | C13: 45985 | D13: 0.33333333 | E13: 0.33333333 | H13: 7
F34: TOPLAMLAR | G34: =SUM(G7:G33) -> 20 | H34: =SUM(H7:H33) -> 11
F36: KALAN FARK(-/+) | H36: =G34-H34 -> 9

Sheet 14
A1: ADI SOYADI | B1: ='ANA SAYFA'!B15 -> HİLMİ ÖZDEMİR | C1: PERSONEL İZİN ÇİZELGESİ | J1: ANA SAYFA
A2: T.C.KİMLİK NO | B2: ='ANA SAYFA'!D15 -> 50626705742
A3: GÖREVİ | B3: ='ANA SAYFA'!C15 -> OPERATÖR
A4: İŞE GİRİŞ TARİHİ | B4: ='ANA SAYFA'!E15 -> 41477
A5: DOĞUM TARİHİ | B5: ='ANA SAYFA'!F15 -> 26104
A6: İZİN NEDENİ | B6: İZİNE ÇIKIŞ TARİHİ | C6: İZİNDEN DÖNÜŞ TARİHİ | D6: İZİNE ÇIKIŞ SAATİ | E6: İZİNDEN DÖNÜŞ SAATİ | F6: İZNİ KAZANDIĞI TARİH ARALIĞI | G6: SENELİK İZİN HAKKI TUTARI | H6: KULLANILAN İZİN TUTARI
B7: 41918 | C7: 41932 | D7: 0.33333333 | E7: 0.33333333 | F7: 22.07.13-22.07.14 | G7: 14 | H7: 12
B8: 42310 | C8: 42331 | D8: 0.33333333 | E8: 0.33333333 | F8: 22.07.14-22.07.15 | G8: 14 | H8: 18
B9: 42632 | C9: 42644 | D9: 0.33333333 | E9: 0.33333333 | F9: 22.07.15-22.07.16 | G9: 14 | H9: 11
B10: 43017 | C10: 43024 | D10: 0.33333333 | E10: 0.33333333 | F10: 22.07.16-22.07.17 | G10: 14 | H10: 6
B11: 43424 | C11: 43428 | D11: 0.33333333 | E11: 0.33333333 | F11: 22.07.17-22.07.18 | G11: 14 | H11: 4
B12: 43815 | C12: 43825 | D12: 0.33333333 | E12: 0.33333333 | F12: 22.07.18-22.07.19 | G12: 20 | H12: 9
A13: 28 Günlük İzin 24.08.24 Tarihinde Ödenmiştir. | B13: 44102 | C13: 44117 | D13: 0.33333333 | E13: 0.33333333 | F13: 22.07.19-22.07.20 | G13: 20 | H13: 14
B14: 44298 | C14: 44308 | D14: 0.33333333 | E14: 0.33333333 | F14: 16.03.21-16.03.22 | G14: 20 | H14: 10
B15: 44652 | C15: 44674 | D15: 0.33333333 | E15: 0.33333333 | F15: 07.03.23-07.03.24 | G15: 20 | H15: 20
B16: 44680 | C16: 7 Mayıs 2022 Cumartesi | D16: 0.33333333 | E16: 0.33333333 | F16: 07.03.24-07.03.25 | G16: 20 | H16: 4
B17: 45088 | C17: 45103 | D17: 0.33333333 | E17: 0.33333333 | H17: 14
B18: 45250 | C18: 45262 | D18: 0.33333333 | E18: 0.33333333 | H18: 12
B19: 45490 | C19: 45488 | D19: 0.33333333 | E19: 0.33333333 | H19: 14
B20: 45530 | C20: 45531 | D20: 0.33333333 | E20: 0.33333333 | H20: 2
B21: 45749 | C21: 45749 | D21: 0.33333333 | E21: 0.33333333 | H21: 1
F34: TOPLAMLAR | G34: =SUM(G7:G33) -> 170 | H34: =SUM(H7:H33) -> 151
F36: KALAN FARK(-/+) | H36: =G34-H34 -> 19
A37: 41477 | B37: İşe giriş
A38: 44236 | B38: İşten Ayrılış
A39: 44271 | B39: İşe Giriş
A40: 44991 | B40: İşten Ayrılış | C40: Emeklilik-Tazminat Ödemesi
A41: 44992 | B41: İşe Giriş
A42: 45528 | B42: İşten Ayrılış | C42: Tazminat Ödendi
A43: 45566 | B43: İşe giriş | C43: Çalışmaya Devam Ediyor
A45: 56 Günlük İzin 28.03.25 Tarihinde Ödenmiştir. Hesabı kapatılmıştır.

Sheet 15
A1: ADI SOYADI | B1: ='ANA SAYFA'!B16 -> HASAN KURT | C1: PERSONEL İZİN ÇİZELGESİ | J1: ANA SAYFA
A2: T.C.KİMLİK NO | B2: ='ANA SAYFA'!D16 -> 10017059328
A3: GÖREVİ | B3: ='ANA SAYFA'!C16 -> SATIN ALMA SORUMLUSU
A4: İŞE GİRİŞ TARİHİ | B4: ='ANA SAYFA'!E16 -> 45477
A5: DOĞUM TARİHİ | B5: ='ANA SAYFA'!F16 -> 33492
A6: İZİN NEDENİ | B6: İZİNE ÇIKIŞ TARİHİ | C6: İZİNDEN DÖNÜŞ TARİHİ | D6: İZİNE ÇIKIŞ SAATİ | E6: İZİNDEN DÖNÜŞ SAATİ | F6: İZNİ KAZANDIĞI TARİH ARALIĞI | G6: SENELİK İZİN HAKKI TUTARI | H6: KULLANILAN İZİN TUTARI
B7: 45584 | C7: 45584 | D7: 0.33333333 | E7: 0.33333333 | F7: 4.07.2024-4.07.2025 | G7: 14 | H7: 1
B8: 45587 | C8: 45587 | D8: 0.33333333 | E8: 0.33333333 | H8: 1
B9: 45671 | C9: 45671 | D9: 0.33333333 | E9: 0.33333333 | H9: 1
B10: 45686 | C10: 45686 | D10: 0.5 | E10: 0.33333333 | H10: 0.5
B11: 45752 | C11: 45752 | D11: 0.33333333 | E11: 0.45833333 | H11: 0.5
B12: 45784 | C12: 45784 | D12: 0.33333333 | E12: 0.33333333 | H12: 1
B13: 45852 | C13: 45852 | D13: 0.33333333 | E13: 0.33333333 | H13: 1
B14: 45861 | C14: 45861 | D14: 0.33333333 | E14: 0.52083333 | H14: 0.5
B15: 45898 | C15: 45898 | D15: 0.33333333 | E15: 0.52083333 | H15: 0.5
B16: 45983 | C16: 45985 | D16: 0.33333333 | E16: 0.33333333 | H16: 1
B17: 46165 | C17: 46174 | H17: 2
F31: TOPLAMLAR | G31: =SUM(G5:G30) -> 14 | H31: =SUM(H7:H30) -> 10
F33: KALAN FARK(-/+) | H33: =G31-H31 -> 4

Sheet 16
A1: ADI SOYADI | B1: ='ANA SAYFA'!B17 -> HÜSAMETTİN GÜLTEKİN | C1: PERSONEL İZİN ÇİZELGESİ | J1: ANA SAYFA
A2: T.C.KİMLİK NO | B2: ='ANA SAYFA'!D17 -> 40033015848
A3: GÖREVİ | B3: ='ANA SAYFA'!C17 -> KÜREKÇİ
A4: İŞE GİRİŞ TARİHİ | B4: ='ANA SAYFA'!E17 -> 44937
A5: DOĞUM TARİHİ | B5: ='ANA SAYFA'!F17 -> 30752
A6: İZİN NEDENİ | B6: İZİNE ÇIKIŞ TARİHİ | C6: İZİNDEN DÖNÜŞ TARİHİ | D6: İZİNE ÇIKIŞ SAATİ | E6: İZİNDEN DÖNÜŞ SAATİ | F6: İZNİ KAZANDIĞI TARİH ARALIĞI | G6: SENELİK İZİN HAKKI TUTARI | H6: KULLANILAN İZİN TUTARI
B7: 44363 | C7: 44363 | D7: 0.54166667 | E7: 0.75 | F7: 27.07.21-27.07.22 | G7: 14 | H7: 0.5
B8: 44441 | C8: 44442 | D8: 0.33333333 | E8: 0.33333333 | F8: 27.07.22-27.07.23 | G8: 14 | H8: 1
B9: 44410 | C9: 44411 | D9: 0.33333333 | E9: 0.33333333 | F9: 27.07.23-27.07.24 | G9: 14 | H9: 1
B10: 44478 | C10: 44480 | D10: 0.54166667 | E10: 0.33333333 | H10: 0.5
B11: 44468 | C11: 44469 | D11: 0.33333333 | E11: 0.33333333 | H11: 0.5
B12: 44536 | C12: 44537 | D12: 0.33333333 | E12: 0.33333333 | H12: 1
B13: 44537 | C13: 44537 | D13: 0.33333333 | E13: 0.5 | H13: 0.5
B14: 44568 | C14: 44568 | D14: 0.54166667 | E14: 0.75 | H14: 0.5
B15: 44574 | C15: 44575 | D15: 0.33333333 | E15: 0.33333333 | H15: 1
B16: 44587 | C16: 44588 | D16: 0.33333333 | E16: 0.33333333 | H16: 1
B17: 44624 | C17: 44624 | D17: 0.33333333 | E17: 0.75 | H17: 1
B18: 44635 | C18: 44635 | D18: 0.33333333 | E18: 0.75 | H18: 1
B19: 44694 | C19: 44694 | D19: 0.33333333 | E19: 0.66666667 | H19: 0.5
B20: 44991 | C20: 44992 | D20: 0.33333333 | E20: 0.33333333 | H20: 1
B21: 44974 | C21: 44975 | D21: 0.5 | E21: 0.33333333 | H21: 0.5
B22: 45062 | C22: 45063 | D22: 0.33333333 | E22: 0 | H22: 1
F37: TOPLAMLAR | G37: =SUM(G5:G36) -> 42 | H37: =SUM(H7:H36) -> 12.5
F39: KALAN FARK(-/+) | H39: =G37-H37 -> 29.5

Sheet 17
A1: ADI SOYADI | B1: ='ANA SAYFA'!B18 -> AHMET SAVAŞ | C1: PERSONEL İZİN ÇİZELGESİ
A2: T.C.KİMLİK NO | B2: ='ANA SAYFA'!D18 -> 28546398634
A3: GÖREVİ | B3: ='ANA SAYFA'!C18 -> KAMYON ŞOFÖRÜ
A4: İŞE GİRİŞ TARİHİ | B4: ='ANA SAYFA'!E18 -> 44928
A5: DOĞUM TARİHİ | B5: ='ANA SAYFA'!F18 -> 25461
A6: PERSONEL İZİN ÇİZELGESİ | J6: Ana Sayfa
A7: İZİN NEDENİ | B7: İZİNE ÇIKIŞ TARİHİ | C7: İZİNDEN DÖNÜŞ TARİHİ | D7: İZİNE ÇIKIŞ SAATİ | E7: İZİNDEN DÖNÜŞ SAATİ | F7: İZNİ KAZANDIĞI TARİH ARALIĞI | G7: SENELİK İZİN HAKKI TUTARI | H7: KULLANILAN İZİN TUTARI
B8: 45035 | C8: 45040 | D8: 0.33333333 | E8: 0.33333333 | F8: 02.01.2023-02.01.2024 | G8: 20 | H8: 1
F9: 02.01.2024-02.01.2025 | G9: 20
F35: TOPLAMLAR | G35: =SUM(G5:G34) -> 40 | H35: =SUM(H8:H34) -> 1
F37: KALAN FARK(-/+) | H37: =G35-H35 -> 39

Sheet 18
A1: ADI SOYADI | B1: ='ANA SAYFA'!B19 -> ALPEREN TORUK | C1: PERSONEL İZİN ÇİZELGESİ
A2: T.C.KİMLİK NO | B2: ='ANA SAYFA'!D19 -> 29221711892
A3: GÖREVİ | B3: ='ANA SAYFA'!C19 -> TIR-ÇEKİCİ ŞOFÖRÜ
A4: İŞE GİRİŞ TARİHİ | B4: ='ANA SAYFA'!E19 -> 45434
A5: DOĞUM TARİHİ | B5: ='ANA SAYFA'!F19 -> 36442
A6: PERSONEL İZİN ÇİZELGESİ | J6: Ana Sayfa
A7: İZİN NEDENİ | B7: İZİNE ÇIKIŞ TARİHİ | C7: İZİNDEN DÖNÜŞ TARİHİ | D7: İZİNE ÇIKIŞ SAATİ | E7: İZİNDEN DÖNÜŞ SAATİ | F7: İZNİ KAZANDIĞI TARİH ARALIĞI | G7: SENELİK İZİN HAKKI TUTARI | H7: KULLANILAN İZİN TUTARI
B8: 45463 | C8: 45467 | D8: 0.33333333 | E8: 0.33333333 | F8: 22.05.2024-22.05.2025 | G8: 14 | H8: 3
B9: TEMMUZ 2024 MAAŞINDAN YAPILAN KESİNTİ | F9: 22.05.2025-22.05.26 | G9: 14 | H9: -3
B10: 45573 | C10: 45573 | D10: 0.5 | E10: 0.33333333 | H10: 0.5
B11: 45652 | C11: 45652 | D11: 0.33333333 | E11: 0.33333333 | H11: 1
B12: 45677 | C12: 45677 | D12: 0.33333333 | E12: 0.33333333 | H12: 1
B13: 29 nisan 2025 Salı | C13: 29 nisan 2025 Salı | D13: 0.33333333 | E13: 0.33333333 | H13: 1
B14: NİSAN 2025 MAAŞINDAN YAPILAN KESİNTİ | H14: -2
B15: MAYIS 2025 MAAŞINDAN YAPILAN KESİNTİ | H15: -1
B16: 45950 | C16: 45951 | H16: 1
B17: 45957 | C17: 45964 | H17: 5 | J17: 45959
B18: 46081 | C18: 46081 | D18: 0.375 | E18: 0.5 | H18: 0.5
B19: 46174 | C19: 46177 | H19: 3
B20: 46209 | C20: 46180 | H20: 1
B25: ,
F29: TOPLAMLAR | G29: =SUM(G5:G28) -> 28 | H29: =SUM(H8:H28) -> 11
F31: KALAN FARK(-/+) | H31: =G29-H29 -> 17

Sheet 19
A1: ADI SOYADI | B1: ='ANA SAYFA'!B20 -> İBRAHİM KURT | C1: PERSONEL İZİN ÇİZELGESİ | J1: ANA SAYFA
A2: T.C.KİMLİK NO | B2: ='ANA SAYFA'!D20 -> 69652051396
A3: GÖREVİ | B3: ='ANA SAYFA'!C20 -> İŞ MAK. BAKIM VE ONARIM
A4: İŞE GİRİŞ TARİHİ | B4: ='ANA SAYFA'!E20 -> 44601
A5: DOĞUM TARİHİ | B5: ='ANA SAYFA'!F20 -> 27792
A6: İZİN NEDENİ | B6: İZİNE ÇIKIŞ TARİHİ | C6: İZİNDEN DÖNÜŞ TARİHİ | D6: İZİNE ÇIKIŞ SAATİ | E6: İZİNDEN DÖNÜŞ SAATİ | F6: İZNİ KAZANDIĞI TARİH ARALIĞI | G6: SENELİK İZİN HAKKI TUTARI | H6: KULLANILAN İZİN TUTARI
B7: 45170 | C7: 45173 | D7: 0.5 | E7: 0.33333333 | F7: 09.02.22-09.02.23 | G7: 14 | H7: 1.5
B8: 45201 | C8: 45215 | D8: 0.33333333 | E8: 0.33333333 | F8: 09.02.23-09.02.24 | G8: 14 | H8: 12
B9: 45463 | C9: 45481 | D9: 0.33333333 | E9: 0.33333333 | F9: 09.02.24-09.02.25 | G9: 14 | H9: 15
B10: 45528 | C10: 45528 | D10: 0.33333333 | E10: 0.33333333 | F10: 09.02.25-09.02.26 | G10: 14 | H10: 1
B11: 45540 | C11: 45540 | D11: 0.5 | E11: 0.33333333 | H11: 0.5
B12: AĞUSTOS 2024 MAAŞINDAN YAPILAN KESİNTİ | H12: -1
B13: 45642 | C13: 45657 | D13: 800 | E13: 0.33333333 | H13: 14
B14: ARALIK 2024 MAAŞINDAN YAPILAN KESİNTİ | H14: -3
B15: 45766 | C15: 45768 | D15: 0.33333333 | E15: 0.33333333 | H15: 1
B16: 45882 | C16: 45883 | D16: 0.33333333 | E16: 0.33333333 | H16: 0.5
B17: 45941 | C17: 45942 | H17: 1
B18: 46013 | C18: 46020 | H18: 6
B19: 46167 | C19: 46181 | H19: 7
F28: TOPLAMLAR | G28: =SUM(G5:G27) -> 56 | H28: =SUM(H7:H27) -> 55.5
F30: KALAN FARK(-/+) | H30: =G28-H28 -> 0.5

Sheet 20
A1: ADI SOYADI | B1: ='ANA SAYFA'!B21 -> İBRAHİM SEVEN | C1: PERSONEL İZİN ÇİZELGESİ | J1: ANA SAYFA
A2: T.C.KİMLİK NO | B2: ='ANA SAYFA'!D21 -> 28438730016
A3: GÖREVİ | B3: ='ANA SAYFA'!C21 -> TIR ŞOFÖRÜ
A4: İŞE GİRİŞ TARİHİ | B4: ='ANA SAYFA'!E21 -> 44946
A5: DOĞUM TARİHİ | B5: ='ANA SAYFA'!F21 -> 28074
A6: İZİN NEDENİ | B6: İZİNE ÇIKIŞ TARİHİ | C6: İZİNDEN DÖNÜŞ TARİHİ | D6: İZİNE ÇIKIŞ SAATİ | E6: İZİNDEN DÖNÜŞ SAATİ | F6: İZNİ KAZANDIĞI TARİH ARALIĞI | G6: SENELİK İZİN HAKKI TUTARI | H6: KULLANILAN İZİN TUTARI
A7: İLK İŞE GİRİŞ 20.08.2004 | B7: 10.01.2023 Tarihinde Devir Alacağı İzin Tutarı | G7: 28
B8: 44927 | C8: 44941 | D8: 0.33333333 | E8: 0.33333333 | F8: 20.01.23-20.01.24 | G8: 26 | H8: 12 | I8: ÖDENDİ
B9: 44990 | C9: 45000 | D9: 0.33333333 | E9: 0.33333333 | F9: 20.01.24-20.01.25 | G9: 26 | H9: 8 | I9: ÖDENDİ
B10: 45042 | C10: 45043 | D10: 0.33333333 | E10: 0.33333333 | F10: 20.01.25-20.01.26 | G10: 26 | H10: 1 | K10: 45505 | L10: e KADAR TAZMİNATINI ALDI
B11: 45069 | C11: 45070 | D11: 0.33333333 | E11: 0.33333333 | H11: 1
B12: 45131 | C12: 45132 | D12: 0.33333333 | E12: 0.33333333 | H12: 1
B13: 45146 | C13: 45147 | D13: 0.33333333 | E13: 0.33333333 | H13: 1
B14: 45173 | C14: 45174 | D14: 0.33333333 | E14: 0.33333333 | H14: 1
B15: 45198 | C15: 45199 | D15: 0.33333333 | E15: 0.33333333 | H15: 1
B16: 45351 | C16: 45352 | D16: 0.33333333 | E16: 0.33333333 | H16: 1
B17: 45479 | C17: 45481 | D17: 0.33333333 | E17: 0.33333333 | H17: 2
B18: 45491 | C18: 45491 | D18: 0.33333333 | E18: 0.33333333 | H18: 1
B19: 45495 | C19: 45495 | D19: 0.5 | E19: 0.33333333 | H19: 0.5 | L19: =L16-L17 -> 0
B20: 45497 | C20: 45497 | D20: 0.33333333 | E20: 0.33333333 | H20: 1
B21: 45502 | C21: 45502 | D21: 0.5 | E21: 0.33333333 | H21: 0.5
B22: 45525 | C22: 45525 | D22: 0.33333333 | E22: 0.33333333 | H22: 1 | M22: 18
B23: 45546 | C23: 45546 | D23: 0.33333333 | E23: 0.33333333 | H23: 1 | M23: 3
B24: 45505 | C24: 45505 | D24: 0.33333333 | E24: 0.33333333 | H24: 1 | M24: 3
B25: 45561 | C25: 45561 | D25: 0.33333333 | E25: 0.33333333 | H25: 1 | M25: 1
B26: 45598 | C26: 45598 | D26: 0.33333333 | E26: 0.33333333 | H26: 1 | M26: 1
B27: 45735 | C27: 45737 | D27: 0.33333333 | E27: 0.33333333 | H27: 3
B28: 45749 | C28: 45751 | D28: 0.33333333 | E28: 0.33333333 | H28: 3 | M28: =SUM(M22:M27) -> 26
B29: 45947 | C29: 45948 | D29: 0.33333333 | E29: 0.33333333 | H29: 1
B30: 45957 | C30: 45958 | D30: 0.33333333 | E30: 0.33333333 | H30: 1
B31: 45870 | C31: 45876 | H31: 5
B32: 45908 | C32: 45919 | H32: 10
B33: 45931 | C33: 45948 | H33: 15
B34: 45972 | C34: 45983 | H34: 10
B35: 46006 | C35: 46011 | H35: 5
B36: 46167 | C36: 46176 | H36: 3
B37: 46162 | C37: 46163 | H37: 1
B38: 46174 | C38: 46175 | H38: 1
F41: TOPLAMLAR | G41: =SUM(G5:G40) -> 106 | H41: =SUM(H7:H40) -> 95
F43: KALAN FARK(-/+) | H43: =G41-H41 -> 11

Sheet 21
A1: ADI SOYADI | B1: ='ANA SAYFA'!B22 -> EMİRHAN GÜRBÜZ | C1: PERSONEL İZİN ÇİZELGESİ | J1: ANA SAYFA
A2: T.C.KİMLİK NO | B2: ='ANA SAYFA'!D22 -> 20473884860
A3: GÖREVİ | B3: ='ANA SAYFA'!C22 -> İŞ MAKİNELERİ YAĞCISI
A4: İŞE GİRİŞ TARİHİ | B4: ='ANA SAYFA'!E22 -> 45568
A5: DOĞUM TARİHİ | B5: ='ANA SAYFA'!F22 -> 38058
A6: İZİN NEDENİ | B6: İZİNE ÇIKIŞ TARİHİ | C6: İZİNDEN DÖNÜŞ TARİHİ | D6: İZİNE ÇIKIŞ SAATİ | E6: İZİNDEN DÖNÜŞ SAATİ | F6: İZNİ KAZANDIĞI TARİH ARALIĞI | G6: SENELİK İZİN HAKKI TUTARI | H6: KULLANILAN İZİN TUTARI
B7: 45629 | C7: 45632 | D7: 0.33333333 | E7: 0.33333333 | F7: 03.10.2024-03.10.2025 | H7: 4
B8: KASIM 2024 MAAŞINDAN YAPILAN KESİNTİ | H8: -2
B9: 45681 | C9: 45681 | D9: 0.33333333 | E9: 0.33333333 | H9: 1
B10: OCAK 2025 MAAŞINDAN YAPILAN KESİNTİ | H10: -2
B11: 45719 | C11: 45719 | D11: 0.33333333 | E11: 0.33333333 | H11: 1
B12: 45727 | C12: 45727 | D12: 0.33333333 | E12: 0.33333333 | H12: 1
B13: 45743 | C13: 45740 | D13: 0.33333333 | E13: 0.33333333 | H13: 1
B14: MART 2025 MAAŞINDAN YAPILAN KESİNTİ | H14: -2
B15: NİSAN 2025 MAAŞINDAN YAPILAN KESİNTİ | H15: -2
B16: 46163 | C16: 46174 | H16: 4
F33: TOPLAMLAR | G33: =SUM(G7:G32) -> 0 | H33: =SUM(H7:H32) -> 4
F35: KALAN FARK(-/+) | H35: =G33-H33 -> -4

Sheet 22
A1: ADI SOYADI | B1: ='ANA SAYFA'!B23 -> DOĞAN YAĞMUR | C1: PERSONEL İZİN ÇİZELGESİ | J1: ANA SAYFA
A2: T.C.KİMLİK NO | B2: ='ANA SAYFA'!D23 -> 59386205738
A3: GÖREVİ | B3: ='ANA SAYFA'!C23 -> KAMYON ŞOFÖRÜ
A4: İŞE GİRİŞ TARİHİ | B4: ='ANA SAYFA'!E23 -> 45418
A5: DOĞUM TARİHİ | B5: ='ANA SAYFA'!F23 -> 31973
A6: İZİN NEDENİ | B6: İZİNE ÇIKIŞ TARİHİ | C6: İZİNDEN DÖNÜŞ TARİHİ | D6: İZİNE ÇIKIŞ SAATİ | E6: İZİNDEN DÖNÜŞ SAATİ | F6: İZNİ KAZANDIĞI TARİH ARALIĞI | G6: SENELİK İZİN HAKKI TUTARI | H6: KULLANILAN İZİN TUTARI
B7: 45467 | C7: 45468 | D7: 0.33333333 | E7: 0.33333333 | F7: 06.05.24-06.05.25 | G7: 14 | H7: 1
B8: 45483 | C8: 45483 | D8: 0.33333333 | E8: 0.33333333 | F8: 06.05.25-06.05.26 | G8: 14 | H8: 1
B9: 45502 | C9: 45502 | D9: 0.33333333 | E9: 0.33333333 | H9: 1
B10: 45511 | C10: 45511 | D10: 0.33333333 | E10: 0.33333333 | H10: 1
B11: AĞUSTOS 2024 MAAŞINDAN YAPILAN KESİNTİ | H11: -3
B12: 45590 | C12: 45590 | D12: 0.33333333 | E12: 0.33333333 | H12: 1
B13: KASIM 2024 MAAŞINDAN YAPILAN YAPILAN KESİNTİ | H13: -2
B14: 45789 | C14: 45789 | D14: 0.33333333 | E14: 0.5 | H14: 0.5
B15: 45821 | C15: 45821 | D15: 0.33333333 | E15: 0.33333333 | H15: 1
B16: 45793 | C16: 45793 | D16: 0.33333333 | E16: 0.33333333 | H16: 1
B17: 45825 | C17: 45825 | D17: 0.33333333 | E17: 0.33333333 | H17: 0.5
B18: 45871 | C18: 45871 | D18: 0.33333333 | E18: 0.33333333 | H18: 1
B19: 45887 | C19: 45888 | D19: 0.33333333 | E19: 0.33333333 | H19: 1
B20: 45890 | C20: 45891 | D20: 0.33333333 | E20: 0.33333333 | H20: 1
B21: 45926 | C21: 45927 | D21: 0.33333333 | E21: 0.33333333 | H21: 1
B22: 45936 | C22: 45937 | D22: 0.33333333 | E22: 0.33333333 | H22: 1
B23: 46009 | C23: 46010 | D23: 0.33333333 | E23: 0.33333333 | H23: 1
B24: 46108 | C24: 46109 | H24: 1
B25: 46139 | C25: 46140 | H25: 1 | J25: İMZASIZ
B26: 46197 | C26: 46198 | H26: 1
F38: TOPLAMLAR | G38: =SUM(G5:G37) -> 28 | H38: =SUM(H7:H37) -> 12
F40: KALAN FARK(-/+) | H40: =G38-H38 -> 16

Sheet 23
A1: ADI SOYADI | B1: ='ANA SAYFA'!B24 -> NEVZAT KAŞIKÇI | C1: PERSONEL İZİN ÇİZELGESİ | J1: ANA SAYFA
A2: T.C.KİMLİK NO | B2: ='ANA SAYFA'!D24 -> 39316375052
A3: GÖREVİ | B3: ='ANA SAYFA'!C24 -> BULDOZER OPERATÖRÜ
A4: İŞE GİRİŞ TARİHİ | B4: ='ANA SAYFA'!E24 -> 45404
A5: DOĞUM TARİHİ | B5: ='ANA SAYFA'!F24 -> 22945
A6: İZİN NEDENİ | B6: İZİNE ÇIKIŞ TARİHİ | C6: İZİNDEN DÖNÜŞ TARİHİ | D6: İZİNE ÇIKIŞ SAATİ | E6: İZİNDEN DÖNÜŞ SAATİ | F6: İZNİ KAZANDIĞI TARİH ARALIĞI | G6: SENELİK İZİN HAKKI TUTARI | H6: KULLANILAN İZİN TUTARI
B7: 45482 | C7: 45488 | D7: 0.33333333 | E7: 0.33333333 | F7: 22.04.24-22.04.25 | G7: 20 | H7: 6
A8: TEMMUZ 2024 MAAŞINDAN YAPILAN KESİNTİ | H8: -3
A9: AĞUSTOS 2024 MAAŞINDAN YAPILAN KESİNTİ | H9: -3
B10: 45722 | C10: 45727 | D10: 0.33333333 | E10: 0.33333333 | H10: 5
A11: NİSAN 2025 MAAŞINDAN YAPILAN KESİNTİ | H11: -2
B12: MAYIS MAAŞINDAN YAPILAN KESİNTİ | H12: -3
B13: 45834 | C13: 45836 | D13: 0.33333333 | E13: 0.33333333 | H13: 3
B14: 45869 | C14: 45870 | D14: 0.33333333 | E14: 0.33333333 | H14: 1
B15: 45985 | C15: 45995 | H15: 9 | J15: İMZASIZ
B16: 46015 | C16: 46016 | H16: 1 | J16: İMZASIZ
B17: 46097 | C17: 46099 | H17: 2 | J17: İMZASIZ
F35: TOPLAMLAR | G35: =SUM(G7:G34) -> 20 | H35: =SUM(H7:H34) -> 16
F37: KALAN FARK(-/+) | H37: =G35-H35 -> 4

Sheet 24
A1: ADI SOYADI | B1: MUSTAFA ŞENOL SANCAK | C1: PERSONEL İZİN ÇİZELGESİ | J1: ANA SAYFA
A2: T.C.KİMLİK NO | B2: 19988726864
A3: GÖREVİ | B3: ENDÜSTRİYEL İLİŞKİLER VE PERSONEL İLİŞKİLERİ
A4: İŞE GİRİŞ TARİHİ | B4: 45124
A5: DOĞUM TARİHİ | B5: 24108
A6: İZİN NEDENİ | B6: İZİNE ÇIKIŞ TARİHİ | C6: İZİNDEN DÖNÜŞ TARİHİ | D6: İZİNE ÇIKIŞ SAATİ | E6: İZİNDEN DÖNÜŞ SAATİ | F6: İZNİ KAZANDIĞI TARİH ARALIĞI | G6: SENELİK İZİN HAKKI TUTARI | H6: KULLANILAN İZİN TUTARI
B7: 20/06/2024 Perşembe | C7: 45465 | D7: 0.33333333 | E7: 0.33333333 | F7: 17.07.23-17.07.24 | G7: 20 | H7: 3
B8: 45523 | C8: 45542 | D8: 0.33333333 | E8: 0.33333333 | F8: 17.07.24-17.07.25 | G8: 20 | H8: 18
B9: 45943 | C9: 45955 | H9: 11
B10: 46048 | C10: 46055 | H10: 6
F37: TOPLAMLAR | G37: =SUM(G5:G36) -> 40 | H37: =SUM(H7:H36) -> 38
F39: KALAN FARK(-/+) | H39: =G37-H37 -> 2

Sheet 25
A1: ADI SOYADI | B1: ='ANA SAYFA'!B26 -> HASAN AKÇAYOĞLU | C1: PERSONEL İZİN ÇİZELGESİ | J1: ANA SAYFA
A2: T.C.KİMLİK NO | B2: ='ANA SAYFA'!D26 -> 47494140430
A3: GÖREVİ | B3: ='ANA SAYFA'!C26 -> KAMYON ŞOFÖRÜ
A4: İŞE GİRİŞ TARİHİ | B4: ='ANA SAYFA'!E26 -> 46056
A5: DOĞUM TARİHİ | B5: ='ANA SAYFA'!F26 -> 27560
A6: İZİN NEDENİ | B6: İZİNE ÇIKIŞ TARİHİ | C6: İZİNDEN DÖNÜŞ TARİHİ | D6: İZİNE ÇIKIŞ SAATİ | E6: İZİNDEN DÖNÜŞ SAATİ | F6: İZNİ KAZANDIĞI TARİH ARALIĞI | G6: SENELİK İZİN HAKKI TUTARI | H6: KULLANILAN İZİN TUTARI
B7: 46175 | C7: 46176 | H7: 1
F35: TOPLAMLAR | G35: =SUM(G5:G34) -> 0 | H35: =SUM(H7:H34) -> 1
F37: KALAN FARK(-/+) | H37: =G35-H35 -> -1

Sheet 26
A1: ADI SOYADI | B1: ='ANA SAYFA'!B27 -> MESUT YILMAZ | C1: PERSONEL İZİN ÇİZELGESİ | J1: ANA SAYFA
A2: T.C.KİMLİK NO | B2: ='ANA SAYFA'!D27 -> 39817657916
A3: GÖREVİ | B3: ='ANA SAYFA'!C27 -> USTA YARDIMCISI
A4: İŞE GİRİŞ TARİHİ | B4: ='ANA SAYFA'!E27 -> 41803
A5: DOĞUM TARİHİ | B5: ='ANA SAYFA'!F27 -> 31925
A6: İZİN NEDENİ | B6: İZİNE ÇIKIŞ TARİHİ | C6: İZİNDEN DÖNÜŞ TARİHİ | D6: İZİNE ÇIKIŞ SAATİ | E6: İZİNDEN DÖNÜŞ SAATİ | F6: İZNİ KAZANDIĞI TARİH ARALIĞI | G6: SENELİK İZİN HAKKI TUTARI | H6: KULLANILAN İZİN TUTARI | J6: YENİ İŞE GİRİŞİ YENİ KIDEMİ 02/09/2025
B7: 42223 | C7: 42237 | D7: 0.33333333 | E7: 0.33333333 | F7: 13.06.14-13.06.15 | G7: 14 | H7: 12 | K7: TOPLAM | L7: 511.597,82
B8: 42688 | C8: 42705 | D8: 0.33333333 | E8: 0.33333333 | F8: 13.06.15-13.06.16 | G8: 14 | H8: 15 | J8: 45812 | K8: KIDEM TAZMİNATI | L8: 100000
B9: 42917 | C9: 42929 | D9: 0.33333333 | E9: 0.33333333 | F9: 13.06.16-13.06.17 | G9: 14 | H9: 10 | J9: 45884 | K9: KIDEM TAZMİNATI | L9: 60000
B10: 43437 | C10: 43460 | D10: 0.33333333 | E10: 0.33333333 | F10: 13.06.17-13.06.18 | G10: 14 | H10: 20 | J10: 06/01/2026 vadeli 0271123 nolu çek ile | L10: 351598
B11: 43752 | C11: 43770 | D11: 0.33333333 | E11: 0.33333333 | F11: 13.06.18-13.06.19 | G11: 14 | H11: 16 | J11: YENİ İŞE GİRİŞİ YENİ KIDEMİ 02/09/2025
B12: 44018 | C12: 44043 | D12: 0.33333333 | E12: 0.33333333 | F12: 13.06.19-13.06.20 | G12: 20 | H12: 22
B13: 44422 | C13: 44438 | D13: 0.33333333 | E13: 0.33333333 | F13: 13.06.20-13.06.21 | G13: 20 | H13: 13
B14: 44568 | C14: 44569 | D14: 0.33333333 | E14: 0.33333333 | F14: 13.06.21-13.06.22 | G14: 20 | H14: 1
B15: 44637 | C15: 44639 | D15: 0.33333333 | E15: 0.33333333 | F15: 13.06.22-13.06.23 | G15: 20 | H15: 2
B16: 44712 | C16: 44713 | D16: 0.33333333 | E16: 0.33333333 | F16: 13.06.23-13.06.24 | G16: 20 | H16: 1
B17: 44755 | C17: 44760 | D17: 0.33333333 | E17: 0.33333333 | F17: 13.06.24-13.06.25 | G17: 20 | H17: 4
B18: 44779 | C18: 44781 | D18: 0.33333333 | E18: 0.33333333 | H18: 2
B19: 45008 | C19: 45012 | D19: 0.33333333 | E19: 0.33333333 | H19: 3
B20: 45031 | C20: 45033 | D20: 0.5 | E20: 0.33333333 | H20: 0.5
B21: 45110 | C21: 45111 | D21: 0.33333333 | E21: 0.33333333 | H21: 1
B22: 45119 | C22: 45124 | D22: 0.5 | E22: 0.33333333 | H22: 3.5
B23: 45150 | C23: 45159 | D23: 0.33333333 | E23: 0.33333333 | H23: 7
B24: 45196 | C24: 45201 | D24: 0.33333333 | E24: 0.33333333 | H24: 4
B25: 45269 | C25: 45271 | D25: 0.33333333 | E25: 0.33333333 | H25: 1
B26: 45290 | C26: 45293 | D26: 0.33333333 | E26: 0.33333333 | H26: 1
B27: 01.04.2024 PAZARTESİ | C27: 15.04.2024 PAZARTESİ | D27: 0.33333333 | E27: 0.33333333 | H27: 7
B28: 45463 | C28: 45464 | H28: 2
B29: 45467 | C29: 45468 | H29: 2
B30: 45488 | C30: 45488 | H30: 1
B31: 45518 | C31: 45521 | H31: 4
B32: 45563 | C32: 45563 | H32: 1
B33: 45584 | C33: 45584 | H33: 1
B34: 45681 | C34: 45681 | H34: 1
B35: 45689 | C35: 45689 | H35: 1
B36: 45738 | C36: 45738 | H36: 1
B37: 3 Mayıs 2025 Cumartesi | C37: 3 Mayıs 2025 Cumartesi | H37: 1
B38: 45857 | C38: 45857 | H38: 1
B39: 45871 | C39: 45873 | D39: 0.33333333 | E39: 0.33333333 | H39: 0.5
B40: 45885 | C40: 45901 | D40: 0.33333333 | E40: 0.33333333 | H40: 12
...

Sheet 27
A1: ADI SOYADI | B1: ='ANA SAYFA'!B28 -> MUHAMMET MUSTAFA KOÇYİĞİT | C1: PERSONEL İZİN ÇİZELGESİ | J1: ANA SAYFA
A2: T.C.KİMLİK NO | B2: ='ANA SAYFA'!D28 -> 41989739482
A3: GÖREVİ | B3: ='ANA SAYFA'!C28 -> KEPÇE OPERATÖR
A4: İŞE GİRİŞ TARİHİ | B4: ='ANA SAYFA'!E28 -> 43948
A5: DOĞUM TARİHİ | B5: ='ANA SAYFA'!F28 -> 33312
A6: İZİN NEDENİ | B6: İZİNE ÇIKIŞ TARİHİ | C6: İZİNDEN DÖNÜŞ TARİHİ | D6: İZİNE ÇIKIŞ SAATİ | E6: İZİNDEN DÖNÜŞ SAATİ | F6: İZNİ KAZANDIĞI TARİH ARALIĞI | G6: SENELİK İZİN HAKKI TUTARI | H6: KULLANILAN İZİN TUTARI
B7: 43994 | C7: 43995 | D7: 0.33333333 | E7: 0.33333333 | F7: 27.04.20-27.04.21 | G7: 14 | H7: 1
B8: 44268 | C8: 44268 | D8: 0.54166667 | E8: 018:00 | F8: 27.04.21-27.04.22 | G8: 14 | H8: 0.5
B9: 04.04.2023-11.04.2023 TARİHLERİNDE 5 GÜN BABALIK İZNİ KULLANDI
B10: 45152 | C10: 45155 | D10: 0.33333333 | E10: 0.33333333 | F10: 27.04.22-27.04.23 | G10: 14 | H10: 3
B11: 45210 | C11: 45211 | D11: 0.33333333 | E11: 0.33333333 | F11: 27.04.23-27.04.24 | G11: 14 | H11: 1
B12: 45220 | C12: 45222 | D12: 0.33333333 | E12: 0.33333333 | F12: 27.04.24-27.04.25 | G12: 14 | H12: 1
B13: 45234 | C13: 45236 | D13: 0.5 | E13: 0.33333333 | H13: 0.5
B14: 45287 | C14: 45288 | D14: 0.33333333 | E14: 0.33333333 | H14: 1
B15: 6.04.2024 CUMARTESİ | C15: 15.04.2024 PAZARTESİ | D15: 0.33333333 | E15: 0.33333333 | H15: 2
B16: 45453 | C16: 45472 | H16: 14
B17: 46030 | C17: 46032 | H17: 2
A18: ANNESİ VEFAT ETTİ | B18: 46062 | C18: 46070 | H18: 7 | J18: 3 GÜN CENAZE İZNİ
B19: 46112 | C19: 46116 | H19: 4
F27: TOPLAMLAR | G27: =SUM(G5:G26) -> 70 | H27: =SUM(H7:H26) -> 37
F29: KALAN FARK(-/+) | H29: =G27-H27 -> 33

Sheet 28
A1: ADI SOYADI | B1: ='ANA SAYFA'!B29 -> MUHAMMED AYDIN | C1: PERSONEL İZİN ÇİZELGESİ | J1: ANA SAYFA
A2: T.C.KİMLİK NO | B2: ='ANA SAYFA'!D29 -> 42727968904
A3: GÖREVİ | B3: ='ANA SAYFA'!C29 -> EKSKAVATÖR OPERATÖRÜ
A4: İŞE GİRİŞ TARİHİ | B4: ='ANA SAYFA'!E29 -> 44356
A5: DOĞUM TARİHİ | B5: ='ANA SAYFA'!F29 -> 31968
A6: İZİN NEDENİ | B6: İZİNE ÇIKIŞ TARİHİ | C6: İZİNDEN DÖNÜŞ TARİHİ | D6: İZİNE ÇIKIŞ SAATİ | E6: İZİNDEN DÖNÜŞ SAATİ | F6: İZNİ KAZANDIĞI TARİH ARALIĞI | G6: SENELİK İZİN HAKKI TUTARI | H6: KULLANILAN İZİN TUTARI
B7: 44555 | C7: 44590 | D7: 0.33333333 | E7: 0.33333333 | F7: 09.06.21-09.06.22 | G7: 14 | H7: 30
B8: 44680 | C8: 44690 | D8: 0.33333333 | E8: 0.33333333 | F8: 09.06.22-09.06.23 | G8: 14 | H8: 5
B9: 44749 | C9: 44764 | D9: 0.33333333 | E9: 0.33333333 | F9: 09.06.23-09.06.24 | G9: 14 | H9: 7
B10: 45033 | C10: 45042 | D10: 0.33333333 | E10: 0.33333333 | F10: 09.06.24-09.06.25 | G10: 14 | H10: 5
B11: 45058 | C11: 45064 | D11: 0.5625 | E11: 0.33333333 | H11: 4.5
F30: TOPLAMLAR | G30: =SUM(G7:G29) -> 56 | H30: =SUM(H7:H29) -> 51.5
F32: KALAN FARK(-/+) | H32: =G30-H30 -> 4.5

Sheet 29
A1: ADI SOYADI | B1: ='ANA SAYFA'!B30 -> MUHİTTİN DEMİR | C1: PERSONEL İZİN ÇİZELGESİ | J1: ANA SAYFA
A2: T.C.KİMLİK NO | B2: ='ANA SAYFA'!D30 -> 12361925380
A3: GÖREVİ | B3: ='ANA SAYFA'!C30 -> KAMYON ŞOFÖRÜ
A4: İŞE GİRİŞ TARİHİ | B4: ='ANA SAYFA'!E30 -> 45442
A5: DOĞUM TARİHİ | B5: ='ANA SAYFA'!F30 -> 22324
A6: İZİN NEDENİ | B6: İZİNE ÇIKIŞ TARİHİ | C6: İZİNDEN DÖNÜŞ TARİHİ | D6: İZİNE ÇIKIŞ SAATİ | E6: İZİNDEN DÖNÜŞ SAATİ | F6: İZNİ KAZANDIĞI TARİH ARALIĞI | G6: SENELİK İZİN HAKKI TUTARI | H6: KULLANILAN İZİN TUTARI
A7: 45442 | B7: KIDEM TAZMİNATINDAN SONRA DEVREDEN İZİN | G7: 33
F35: TOPLAMLAR | G35: =SUM(G7:G34) -> 33 | H35: =SUM(H7:H34) -> 0
F37: KALAN FARK(-/+) | H37: =G35-H35 -> 33

Sheet 30
A1: ADI SOYADI | B1: ='ANA SAYFA'!B31 -> MUHSİN ZEDEF | C1: PERSONEL İZİN ÇİZELGESİ | J1: ANA SAYFA
A2: T.C.KİMLİK NO | B2: ='ANA SAYFA'!D31 -> 10982000370
A3: GÖREVİ | B3: ='ANA SAYFA'!C31 -> BEKÇİ
A4: İŞE GİRİŞ TARİHİ | B4: ='ANA SAYFA'!E31 -> 43560
A5: DOĞUM TARİHİ | B5: ='ANA SAYFA'!F31 -> 21491
A6: İZİN NEDENİ | B6: İZİNE ÇIKIŞ TARİHİ | C6: İZİNDEN DÖNÜŞ TARİHİ | D6: İZİNE ÇIKIŞ SAATİ | E6: İZİNDEN DÖNÜŞ SAATİ | F6: İZNİ KAZANDIĞI TARİH ARALIĞI | G6: SENELİK İZİN HAKKI TUTARI | H6: KULLANILAN İZİN TUTARI
F8: 05.04.19-05.04.20 | G8: 20
F9: 05.04.20-05.04.21 | G9: 20 | L9: 43560
B10: 44755 | C10: 44760 | D10: 0.33333333 | E10: 0.33333333 | F10: 05.04.21-05.04.22 | G10: 20 | H10: 4 | K10: resmi giriş | L10: 44471
B11: 44828 | C11: 44830 | D11: 0.33333333 | E11: 0.33333333 | F11: 05.04.22-05.04.23 | G11: 20 | H11: 1 | L11: 45900 | M11: e kadar kıdemini aldı
B12: 45114 | C12: 45117 | D12: 0.33333333 | E12: 0.33333333 | F12: 05.04.23-05.04.24 | G12: 20 | H12: 2 | L12: 45901 | M12: yeni işe giriş kıdem başlama
B13: 45562 | C13: 45565 | D13: 0.33333333 | E13: 0.33333333 | F13: 05.04.24-05.04.25 | G13: 20 | H13: 3
B14: 46003 | C14: 46005 | H14: 2 | J14: İMZASIZ
B15: 46048 | C15: 46050 | H15: 2 | J15: İMZASIZ
F28: TOPLAMLAR | G28: =SUM(G7:G27) -> 120 | H28: =SUM(H7:H27) -> 14
F30: KALAN FARK(-/+) | H30: =G28-H28 -> 106
A31: NOTLAR;
A32: KAZA GECİRDİGİNDEN DOLAYI 25 BİN TL YATIRILDI , KIDEM TAZMİNATINDAN DÜSÜLECEK
A34: ÇALIŞMADAN ÖDENEN ÜCRETLER (RAPORLU)
A35: 2024-ARALIK | B35: 4017.17 | C35: 45660 | D35: KIDEM
A36: 2025-OCAK | B36: 25000 | C36: 45700 | D36: KIDEM
A37: 2025-ŞUBAT | B37: 25000 | C37: 45723 | D37: KIDEM
A38: 2025-MART | B38: 25000 | C38: 45744 | D38: KIDEM
A39: 2025-NİSAN | B39: 25000 | C39: 45786 | D39: KIDEM
A40: 2025-MAYIS | B40: 25000 | C40: 45812 | D40: KIDEM
A41: 2025-HAZİRAN | B41: 25000 | C41: 45842 | D41: KIDEM
A42: TOPLAM | B42: =SUM(B35:B41) -> 154017.17
A43: KIDEM | B43: 167833.66
A44: KALAN | B44: =+B43-B42 -> 13816.49 | C44: 10 kasım da yatacak
A47: YENİ İŞE GİRİŞ | B47: 45903
G50: EMEKLİ ASGARİ | H50: 23762.53
H51: =+H50/30 -> 792.08433
H52: 25000
H53: =+H52/H51 -> 31.562296
G56: 43560
G57: 45657
G59: 45657 | H59: 65921
G60: 13 AYLIK | H60: =+H59/3 -> 21973.667
G61: AYLIK | H61: =+H60/13 -> 1690.2821
F62: (31.12.2024-05.04.2019 | G62: 68 AYLIK | H62: =+H61*68 -> 114939.18
...

Sheet 31
A1: ADI SOYADI | B1: ='ANA SAYFA'!B32 -> MURAT ÖZSUBAŞI | C1: PERSONEL İZİN ÇİZELGESİ | J1: ANA SAYFA
A2: T.C.KİMLİK NO | B2: ='ANA SAYFA'!D32 -> 31463194012
A3: GÖREVİ | B3: ='ANA SAYFA'!C32 -> EKSKAVATÖR OPERATÖRÜ
A4: İŞE GİRİŞ TARİHİ | B4: ='ANA SAYFA'!E32 -> 41505
A5: DOĞUM TARİHİ | B5: ='ANA SAYFA'!F32 -> 26826
A6: İZİN NEDENİ | B6: İZİNE ÇIKIŞ TARİHİ | C6: İZİNDEN DÖNÜŞ TARİHİ | D6: İZİNE ÇIKIŞ SAATİ | E6: İZİNDEN DÖNÜŞ SAATİ | F6: İZNİ KAZANDIĞI TARİH ARALIĞI | G6: SENELİK İZİN HAKKI TUTARI | H6: KULLANILAN İZİN TUTARI
B7: 41618 | C7: 41619 | D7: 0.3125 | E7: 0.3125 | F7: 18.08.13-19.08.14 | G7: 14 | H7: 1
B8: 41619 | C8: 41624 | D8: 0.51041667 | E8: 0.3125 | F8: 19.08.14-19.08.15 | G8: 14 | H8: 3
B9: 41752 | C9: 41753 | D9: 0.52083333 | E9: 0.3125 | F9: 19.08.15-19.08.16 | G9: 14 | H9: 0.5
B10: 41769 | C10: 41771 | D10: 0.33333333 | E10: 0.3125 | F10: 19.08.16-19.08.17 | G10: 14 | H10: 1
B11: 41965 | C11: 41966 | D11: 0.33333333 | E11: 0.3125 | F11: 19.08.17-19.08.18 | G11: 14 | H11: 1
B12: 42054 | C12: 42059 | D12: 0.33333333 | E12: 0.5 | F12: 19.08.18-19.08.19 | G12: 20 | H12: 4.5
B13: 42124 | C13: 42128 | D13: 0.54166667 | E13: 0.3125 | F13: 19.08.19-19.08.20 | G13: 20 | H13: 2.5
B14: 42217 | C14: 42221 | D14: 0.75 | E14: 0.33333333 | F14: 19.08.20-19.08.21 | G14: 20 | H14: 2
B15: 42294 | C15: 42296 | D15: 0.39583333 | E15: 0.33333333 | F15: 19.08.21-19.08.22 | G15: 20 | H15: 1
B16: 42545 | C16: 42546 | D16: 0.33333333 | E16: 0.33333333 | F16: 19.08.22-19.08.23 | G16: 20 | H16: 1
B17: 42632 | C17: 42633 | D17: 0.5 | E17: 0.33333333 | F17: 19.08.23-19.08.24 | G17: 20 | H17: 0.5
B18: 42713 | C18: 42716 | D18: 0.33333333 | E18: 0.33333333 | F18: 19.08.24-19.08.25 | G18: 20 | H18: 2
B19: 42902 | C19: 42914 | D19: 0.33333333 | E19: 0.33333333 | H19: 9
B20: 43176 | C20: 43182 | D20: 0.33333333 | E20: 0.33333333 | H20: 5
B21: 43200 | C21: 43201 | D21: 0.33333333 | E21: 0.33333333 | H21: 1
B22: 43297 | C22: 43298 | D22: 0.33333333 | E22: 0.33333333 | H22: 1
B23: 43302 | C23: 43304 | D23: 0.33333333 | E23: 0.33333333 | H23: 1
A24: ÜCRETİ ÖDENEREK RESMİ BORDRO İMZALATILDI. | H24: 19
B25: 43384 | C25: 43386 | D25: 0.33333333 | E25: 0.33333333 | H25: 1
B26: 43412 | C26: 43127 | D26: 0.33333333 | E26: 0.33333333 | H26: 10
